Workbook

Sheet 高一2026
A1: 序号 | B1: 年级 | C1: 班级 | D1: 姓名 | E1: 性别 | F1: 50m | G1: 得分 | H1: 体前屈 | I1: 得分 | J1: 跳远 | K1: 得分 | L1: 引/仰 | M1: 得分 | N1: 附加值 | O1: 附加1 | P1: 引/仰总分 | Q1: 耐久跑 | R1: 得分 | S1: 附加值 | T1: 附加2 | U1: 长跑总分 | V1: 平均分 | W1: 附加分 | X1: 最终实际得分 | Y1: 最终得分 | Z1: 备注
A2: 27 | B2: 高一 | C2: 101 | D2: 邵启铖 | E2: 男 | F2: 7.1 | G2: =IF(B2="高三",IF($E2="男",LOOKUP(F2,[1]对照表!$G$3:$G$24,[1]对照表!$H$3:$H$24),LOOKUP(F2,[1]对照表!$G$27:$G$48,[1]对照表!$H$27:$H$48)),IF(B2="高二",IF($E2="男",LOOKUP(F2,[1]对照表!$F$3:$F$24,[1]对照表!$H$3:$H$24),LOOKUP(F2,[1]对照表!$F$27:$F$48,[1]对照表!$H$27:$H$48)),IF(B2="高一",IF($E2="男",LOOKUP(F2,[1]对照表!$E$3:$E$24,[1]对照表!$H$3:$H$24),LOOKUP(F2,[1]对照表!$E$27:$E$48,[1]对照表!$H$27:$H$48))))) -> 100 | H2: 15.9 | I2: =IF(B2="高三",IF($E2="男",LOOKUP(H2,[1]对照表!$K$3:$K$24,[1]对照表!$L$3:$L$24),LOOKUP(H2,[1]对照表!$K$27:$K$48,[1]对照表!$L$27:$L$48)),IF(B2="高二",IF($E2="男",LOOKUP(H2,[1]对照表!$J$3:$J$24,[1]对照表!$L$3:$L$24),LOOKUP(H2,[1]对照表!$J$27:$J$48,[1]对照表!$L$27:$L$48)),IF(B2="高一",IF($E2="男",LOOKUP(H2,[1]对照表!$I$3:$I$24,[1]对照表!$L$3:$L$24),LOOKUP(H2,[1]对照表!$I$27:$I$48,[1]对照表!$L$27:$L$48))))) -> 80 | J2: 247 | K2: =IF(B2="高三",IF($E2="男",LOOKUP(J2,[1]对照表!$O$3:$O$24,[1]对照表!$P$3:$P$24),LOOKUP(J2,[1]对照表!$O$27:$O$48,[1]对照表!$P$27:$P$48)),IF(B2="高二",IF($E2="男",LOOKUP(J2,[1]对照表!$N$3:$N$24,[1]对照表!$P$3:$P$24),LOOKUP(J2,[1]对照表!$N$27:$N$48,[1]对照表!$P$27:$P$48)),IF(B2="高一",IF($E2="男",LOOKUP(J2,[1]对照表!$M$3:$M$24,[1]对照表!$P$3:$P$24),LOOKUP(J2,[1]对照表!$M$27:$M$48,[1]对照表!$P$27:$P$48))))) -> 85 | L2: 20 | M2: =IF(B2="高三",IF($E2="男",LOOKUP(L2,[1]对照表!$S$3:$S$24,[1]对照表!$T$3:$T$24),LOOKUP(L2,[1]对照表!$S$27:$S$48,[1]对照表!$T$27:$T$48)),IF(B2="高二",IF($E2="男",LOOKUP(L2,[1]对照表!$R$3:$R$24,[1]对照表!$T$3:$T$24),LOOKUP(L2,[1]对照表!$R$27:$R$48,[1]对照表!$T$27:$T$48)),IF(B2="高一",IF($E2="男",LOOKUP(L2,[1]对照表!$Q$3:$Q$24,[1]对照表!$T$3:$T$24),LOOKUP(L2,[1]对照表!$Q$27:$Q$48,[1]对照表!$T$27:$T$48))))) -> 100 | N2: =IF(B2="高三",MAX(IF(E2="男",L2-18,L2-55),0),IF(B2="高二",MAX(IF(E2="男",L2-17,L2-54),0),IF(B2="高一",MAX(IF(E2="男",L2-16,L2-53),0)))) -> 4 | O2: =IF(E2="男",LOOKUP($N2,[1]对照表!$Z$3:$Z$13,[1]对照表!$AA$3:$AA$13),LOOKUP($N2,[1]对照表!$Z$15:$Z$25,[1]对照表!$AA$15:$AA$25)) -> 4 | P2: =M2+O2 -> 104 | Q2: 3.13 | R2: =IF(B2="高三",IF($E2="男",LOOKUP(Q2,[1]对照表!$W$3:$W$24,[1]对照表!$X$3:$X$24),LOOKUP(Q2,[1]对照表!$W$27:$W$48,[1]对照表!$X$27:$X$48)),IF(B2="高二",IF($E2="男",LOOKUP(Q2,[1]对照表!$V$3:$V$24,[1]对照表!$X$3:$X$24),LOOKUP(Q2,[1]对照表!$V$27:$V$48,[1]对照表!$X$27:$X$48)),IF(B2="高一",IF($E2="男",LOOKUP(Q2,[1]对照表!$U$3:$U$24,[1]对照表!$X$3:$X$24),LOOKUP(Q2,[1]对照表!$U$27:$U$48,[1]对照表!$X$27:$X$48))))) -> 100 | S2: =ROUND(IF(IF($B2="高三",MIN(IF($E2="男",$Q2-3.2,$Q2-3.2),0),IF($B2="高二",MIN(IF($E2="男",$Q2-3.25,$Q2-3.22),0),IF($B2="高一",MIN(IF($E2="男",$Q2-3.3,$Q2-3.24),0))))<-0.6,IF($B2="高三",MIN(IF($E2="男",$Q2-3.2,$Q2-3.2),0),IF($B2="高二",MIN(IF($E2="男",$Q2-3.25,$Q2-3.22),0),IF($B2="高一",MIN(IF($E2="男",$Q2-3.3,$Q2-3.24),0))))+0.4,IF($B2="高三",MIN(IF($E2="男",$Q2-3.2,$Q2-3.2),0),IF($B2="高二",MIN(IF($E2="男",$Q2-3.25,$Q2-3.22),0),IF($B2="高一",MIN(IF($E2="男",$Q2-3.3,$Q2-3.24),0))))),2) -> -0.17 | T2: =IF(E2="男",LOOKUP($S2,[1]对照表!$AB$3:$AB$13,[1]对照表!$AC$3:$AC$13),LOOKUP($S2,[1]对照表!$AB$15:$AB$25,[1]对照表!$AC$15:$AC$25)) -> 4 | U2: =R2+T2 -> 104 | V2: =SUM(I2,K2,M2)/3*0.3+SUM(G2,R2)/2*0.4 -> 66.5 | W2: =O2+T2 -> 8 | X2: =V2/0.7+W2 -> 103 | Y2: 103
A3: 5 | B3: 高一 | C3: 101 | D3: 陈星铖 | E3: 男 | F3: 7.1 | G3: =IF(B3="高三",IF($E3="男",LOOKUP(F3,[1]对照表!$G$3:$G$24,[1]对照表!$H$3:$H$24),LOOKUP(F3,[1]对照表!$G$27:$G$48,[1]对照表!$H$27:$H$48)),IF(B3="高二",IF($E3="男",LOOKUP(F3,[1]对照表!$F$3:$F$24,[1]对照表!$H$3:$H$24),LOOKUP(F3,[1]对照表!$F$27:$F$48,[1]对照表!$H$27:$H$48)),IF(B3="高一",IF($E3="男",LOOKUP(F3,[1]对照表!$E$3:$E$24,[1]对照表!$H$3:$H$24),LOOKUP(F3,[1]对照表!$E$27:$E$48,[1]对照表!$H$27:$H$48))))) -> 100 | H3: 18 | I3: =IF(B3="高三",IF($E3="男",LOOKUP(H3,[1]对照表!$K$3:$K$24,[1]对照表!$L$3:$L$24),LOOKUP(H3,[1]对照表!$K$27:$K$48,[1]对照表!$L$27:$L$48)),IF(B3="高二",IF($E3="男",LOOKUP(H3,[1]对照表!$J$3:$J$24,[1]对照表!$L$3:$L$24),LOOKUP(H3,[1]对照表!$J$27:$J$48,[1]对照表!$L$27:$L$48)),IF(B3="高一",IF($E3="男",LOOKUP(H3,[1]对照表!$I$3:$I$24,[1]对照表!$L$3:$L$24),LOOKUP(H3,[1]对照表!$I$27:$I$48,[1]对照表!$L$27:$L$48))))) -> 85 | J3: 257 | K3: =IF(B3="高三",IF($E3="男",LOOKUP(J3,[1]对照表!$O$3:$O$24,[1]对照表!$P$3:$P$24),LOOKUP(J3,[1]对照表!$O$27:$O$48,[1]对照表!$P$27:$P$48)),IF(B3="高二",IF($E3="男",LOOKUP(J3,[1]对照表!$N$3:$N$24,[1]对照表!$P$3:$P$24),LOOKUP(J3,[1]对照表!$N$27:$N$48,[1]对照表!$P$27:$P$48)),IF(B3="高一",IF($E3="男",LOOKUP(J3,[1]对照表!$M$3:$M$24,[1]对照表!$P$3:$P$24),LOOKUP(J3,[1]对照表!$M$27:$M$48,[1]对照表!$P$27:$P$48))))) -> 95 | L3: 20 | M3: =IF(B3="高三",IF($E3="男",LOOKUP(L3,[1]对照表!$S$3:$S$24,[1]对照表!$T$3:$T$24),LOOKUP(L3,[1]对照表!$S$27:$S$48,[1]对照表!$T$27:$T$48)),IF(B3="高二",IF($E3="男",LOOKUP(L3,[1]对照表!$R$3:$R$24,[1]对照表!$T$3:$T$24),LOOKUP(L3,[1]对照表!$R$27:$R$48,[1]对照表!$T$27:$T$48)),IF(B3="高一",IF($E3="男",LOOKUP(L3,[1]对照表!$Q$3:$Q$24,[1]对照表!$T$3:$T$24),LOOKUP(L3,[1]对照表!$Q$27:$Q$48,[1]对照表!$T$27:$T$48))))) -> 100 | N3: =IF(B3="高三",MAX(IF(E3="男",L3-18,L3-55),0),IF(B3="高二",MAX(IF(E3="男",L3-17,L3-54),0),IF(B3="高一",MAX(IF(E3="男",L3-16,L3-53),0)))) -> 4 | O3: =IF(E3="男",LOOKUP($N3,[1]对照表!$Z$3:$Z$13,[1]对照表!$AA$3:$AA$13),LOOKUP($N3,[1]对照表!$Z$15:$Z$25,[1]对照表!$AA$15:$AA$25)) -> 4 | P3: =M3+O3 -> 104 | Q3: 3.39 | R3: =IF(B3="高三",IF($E3="男",LOOKUP(Q3,[1]对照表!$W$3:$W$24,[1]对照表!$X$3:$X$24),LOOKUP(Q3,[1]对照表!$W$27:$W$48,[1]对照表!$X$27:$X$48)),IF(B3="高二",IF($E3="男",LOOKUP(Q3,[1]对照表!$V$3:$V$24,[1]对照表!$X$3:$X$24),LOOKUP(Q3,[1]对照表!$V$27:$V$48,[1]对照表!$X$27:$X$48)),IF(B3="高一",IF($E3="男",LOOKUP(Q3,[1]对照表!$U$3:$U$24,[1]对照表!$X$3:$X$24),LOOKUP(Q3,[1]对照表!$U$27:$U$48,[1]对照表!$X$27:$X$48))))) -> 90 | S3: =ROUND(IF(IF($B3="高三",MIN(IF($E3="男",$Q3-3.2,$Q3-3.2),0),IF($B3="高二",MIN(IF($E3="男",$Q3-3.25,$Q3-3.22),0),IF($B3="高一",MIN(IF($E3="男",$Q3-3.3,$Q3-3.24),0))))<-0.6,IF($B3="高三",MIN(IF($E3="男",$Q3-3.2,$Q3-3.2),0),IF($B3="高二",MIN(IF($E3="男",$Q3-3.25,$Q3-3.22),0),IF($B3="高一",MIN(IF($E3="男",$Q3-3.3,$Q3-3.24),0))))+0.4,IF($B3="高三",MIN(IF($E3="男",$Q3-3.2,$Q3-3.2),0),IF($B3="高二",MIN(IF($E3="男",$Q3-3.25,$Q3-3.22),0),IF($B3="高一",MIN(IF($E3="男",$Q3-3.3,$Q3-3.24),0))))),2) -> 0 | T3: =IF(E3="男",LOOKUP($S3,[1]对照表!$AB$3:$AB$13,[1]对照表!$AC$3:$AC$13),LOOKUP($S3,[1]对照表!$AB$15:$AB$25,[1]对照表!$AC$15:$AC$25)) -> 0 | U3: =R3+T3 -> 90 | V3: =SUM(I3,K3,M3)/3*0.3+SUM(G3,R3)/2*0.4 -> 66 | W3: =O3+T3 -> 4 | X3: =V3/0.7+W3 -> 98.285714 | Y3: 98.285714
A4: 1 | B4: 高一 | C4: 101 | D4: 包亦宽 | E4: 男 | F4: 7.1 | G4: =IF(B4="高三",IF($E4="男",LOOKUP(F4,[1]对照表!$G$3:$G$24,[1]对照表!$H$3:$H$24),LOOKUP(F4,[1]对照表!$G$27:$G$48,[1]对照表!$H$27:$H$48)),IF(B4="高二",IF($E4="男",LOOKUP(F4,[1]对照表!$F$3:$F$24,[1]对照表!$H$3:$H$24),LOOKUP(F4,[1]对照表!$F$27:$F$48,[1]对照表!$H$27:$H$48)),IF(B4="高一",IF($E4="男",LOOKUP(F4,[1]对照表!$E$3:$E$24,[1]对照表!$H$3:$H$24),LOOKUP(F4,[1]对照表!$E$27:$E$48,[1]对照表!$H$27:$H$48))))) -> 100 | H4: 20.1 | I4: =IF(B4="高三",IF($E4="男",LOOKUP(H4,[1]对照表!$K$3:$K$24,[1]对照表!$L$3:$L$24),LOOKUP(H4,[1]对照表!$K$27:$K$48,[1]对照表!$L$27:$L$48)),IF(B4="高二",IF($E4="男",LOOKUP(H4,[1]对照表!$J$3:$J$24,[1]对照表!$L$3:$L$24),LOOKUP(H4,[1]对照表!$J$27:$J$48,[1]对照表!$L$27:$L$48)),IF(B4="高一",IF($E4="男",LOOKUP(H4,[1]对照表!$I$3:$I$24,[1]对照表!$L$3:$L$24),LOOKUP(H4,[1]对照表!$I$27:$I$48,[1]对照表!$L$27:$L$48))))) -> 90 | J4: 256 | K4: =IF(B4="高三",IF($E4="男",LOOKUP(J4,[1]对照表!$O$3:$O$24,[1]对照表!$P$3:$P$24),LOOKUP(J4,[1]对照表!$O$27:$O$48,[1]对照表!$P$27:$P$48)),IF(B4="高二",IF($E4="男",LOOKUP(J4,[1]对照表!$N$3:$N$24,[1]对照表!$P$3:$P$24),LOOKUP(J4,[1]对照表!$N$27:$N$48,[1]对照表!$P$27:$P$48)),IF(B4="高一",IF($E4="男",LOOKUP(J4,[1]对照表!$M$3:$M$24,[1]对照表!$P$3:$P$24),LOOKUP(J4,[1]对照表!$M$27:$M$48,[1]对照表!$P$27:$P$48))))) -> 95 | L4: 20 | M4: =IF(B4="高三",IF($E4="男",LOOKUP(L4,[1]对照表!$S$3:$S$24,[1]对照表!$T$3:$T$24),LOOKUP(L4,[1]对照表!$S$27:$S$48,[1]对照表!$T$27:$T$48)),IF(B4="高二",IF($E4="男",LOOKUP(L4,[1]对照表!$R$3:$R$24,[1]对照表!$T$3:$T$24),LOOKUP(L4,[1]对照表!$R$27:$R$48,[1]对照表!$T$27:$T$48)),IF(B4="高一",IF($E4="男",LOOKUP(L4,[1]对照表!$Q$3:$Q$24,[1]对照表!$T$3:$T$24),LOOKUP(L4,[1]对照表!$Q$27:$Q$48,[1]对照表!$T$27:$T$48))))) -> 100 | N4: =IF(B4="高三",MAX(IF(E4="男",L4-18,L4-55),0),IF(B4="高二",MAX(IF(E4="男",L4-17,L4-54),0),IF(B4="高一",MAX(IF(E4="男",L4-16,L4-53),0)))) -> 4 | O4: =IF(E4="男",LOOKUP($N4,[1]对照表!$Z$3:$Z$13,[1]对照表!$AA$3:$AA$13),LOOKUP($N4,[1]对照表!$Z$15:$Z$25,[1]对照表!$AA$15:$AA$25)) -> 4 | P4: =M4+O4 -> 104 | Q4: 3.51 | R4: =IF(B4="高三",IF($E4="男",LOOKUP(Q4,[1]对照表!$W$3:$W$24,[1]对照表!$X$3:$X$24),LOOKUP(Q4,[1]对照表!$W$27:$W$48,[1]对照表!$X$27:$X$48)),IF(B4="高二",IF($E4="男",LOOKUP(Q4,[1]对照表!$V$3:$V$24,[1]对照表!$X$3:$X$24),LOOKUP(Q4,[1]对照表!$V$27:$V$48,[1]对照表!$X$27:$X$48)),IF(B4="高一",IF($E4="男",LOOKUP(Q4,[1]对照表!$U$3:$U$24,[1]对照表!$X$3:$X$24),LOOKUP(Q4,[1]对照表!$U$27:$U$48,[1]对照表!$X$27:$X$48))))) -> 80 | S4: =ROUND(IF(IF($B4="高三",MIN(IF($E4="男",$Q4-3.2,$Q4-3.2),0),IF($B4="高二",MIN(IF($E4="男",$Q4-3.25,$Q4-3.22),0),IF($B4="高一",MIN(IF($E4="男",$Q4-3.3,$Q4-3.24),0))))<-0.6,IF($B4="高三",MIN(IF($E4="男",$Q4-3.2,$Q4-3.2),0),IF($B4="高二",MIN(IF($E4="男",$Q4-3.25,$Q4-3.22),0),IF($B4="高一",MIN(IF($E4="男",$Q4-3.3,$Q4-3.24),0))))+0.4,IF($B4="高三",MIN(IF($E4="男",$Q4-3.2,$Q4-3.2),0),IF($B4="高二",MIN(IF($E4="男",$Q4-3.25,$Q4-3.22),0),IF($B4="高一",MIN(IF($E4="男",$Q4-3.3,$Q4-3.24),0))))),2) -> 0 | T4: =IF(E4="男",LOOKUP($S4,[1]对照表!$AB$3:$AB$13,[1]对照表!$AC$3:$AC$13),LOOKUP($S4,[1]对照表!$AB$15:$AB$25,[1]对照表!$AC$15:$AC$25)) -> 0 | U4: =R4+T4 -> 80 | V4: =SUM(I4,K4,M4)/3*0.3+SUM(G4,R4)/2*0.4 -> 64.5 | W4: =O4+T4 -> 4 | X4: =V4/0.7+W4 -> 96.142857 | Y4: 96.142857
A5: 2 | B5: 高一 | C5: 101 | D5: 曹宸煜 | E5: 男 | F5: 6.9 | G5: =IF(B5="高三",IF($E5="男",LOOKUP(F5,[1]对照表!$G$3:$G$24,[1]对照表!$H$3:$H$24),LOOKUP(F5,[1]对照表!$G$27:$G$48,[1]对照表!$H$27:$H$48)),IF(B5="高二",IF($E5="男",LOOKUP(F5,[1]对照表!$F$3:$F$24,[1]对照表!$H$3:$H$24),LOOKUP(F5,[1]对照表!$F$27:$F$48,[1]对照表!$H$27:$H$48)),IF(B5="高一",IF($E5="男",LOOKUP(F5,[1]对照表!$E$3:$E$24,[1]对照表!$H$3:$H$24),LOOKUP(F5,[1]对照表!$E$27:$E$48,[1]对照表!$H$27:$H$48))))) -> 100 | H5: 13.1 | I5: =IF(B5="高三",IF($E5="男",LOOKUP(H5,[1]对照表!$K$3:$K$24,[1]对照表!$L$3:$L$24),LOOKUP(H5,[1]对照表!$K$27:$K$48,[1]对照表!$L$27:$L$48)),IF(B5="高二",IF($E5="男",LOOKUP(H5,[1]对照表!$J$3:$J$24,[1]对照表!$L$3:$L$24),LOOKUP(H5,[1]对照表!$J$27:$J$48,[1]对照表!$L$27:$L$48)),IF(B5="高一",IF($E5="男",LOOKUP(H5,[1]对照表!$I$3:$I$24,[1]对照表!$L$3:$L$24),LOOKUP(H5,[1]对照表!$I$27:$I$48,[1]对照表!$L$27:$L$48))))) -> 76 | J5: 257 | K5: =IF(B5="高三",IF($E5="男",LOOKUP(J5,[1]对照表!$O$3:$O$24,[1]对照表!$P$3:$P$24),LOOKUP(J5,[1]对照表!$O$27:$O$48,[1]对照表!$P$27:$P$48)),IF(B5="高二",IF($E5="男",LOOKUP(J5,[1]对照表!$N$3:$N$24,[1]对照表!$P$3:$P$24),LOOKUP(J5,[1]对照表!$N$27:$N$48,[1]对照表!$P$27:$P$48)),IF(B5="高一",IF($E5="男",LOOKUP(J5,[1]对照表!$M$3:$M$24,[1]对照表!$P$3:$P$24),LOOKUP(J5,[1]对照表!$M$27:$M$48,[1]对照表!$P$27:$P$48))))) -> 95 | L5: 17 | M5: =IF(B5="高三",IF($E5="男",LOOKUP(L5,[1]对照表!$S$3:$S$24,[1]对照表!$T$3:$T$24),LOOKUP(L5,[1]对照表!$S$27:$S$48,[1]对照表!$T$27:$T$48)),IF(B5="高二",IF($E5="男",LOOKUP(L5,[1]对照表!$R$3:$R$24,[1]对照表!$T$3:$T$24),LOOKUP(L5,[1]对照表!$R$27:$R$48,[1]对照表!$T$27:$T$48)),IF(B5="高一",IF($E5="男",LOOKUP(L5,[1]对照表!$Q$3:$Q$24,[1]对照表!$T$3:$T$24),LOOKUP(L5,[1]对照表!$Q$27:$Q$48,[1]对照表!$T$27:$T$48))))) -> 100 | N5: =IF(B5="高三",MAX(IF(E5="男",L5-18,L5-55),0),IF(B5="高二",MAX(IF(E5="男",L5-17,L5-54),0),IF(B5="高一",MAX(IF(E5="男",L5-16,L5-53),0)))) -> 1 | O5: =IF(E5="男",LOOKUP($N5,[1]对照表!$Z$3:$Z$13,[1]对照表!$AA$3:$AA$13),LOOKUP($N5,[1]对照表!$Z$15:$Z$25,[1]对照表!$AA$15:$AA$25)) -> 1 | P5: =M5+O5 -> 101 | Q5: 3.35 | R5: =IF(B5="高三",IF($E5="男",LOOKUP(Q5,[1]对照表!$W$3:$W$24,[1]对照表!$X$3:$X$24),LOOKUP(Q5,[1]对照表!$W$27:$W$48,[1]对照表!$X$27:$X$48)),IF(B5="高二",IF($E5="男",LOOKUP(Q5,[1]对照表!$V$3:$V$24,[1]对照表!$X$3:$X$24),LOOKUP(Q5,[1]对照表!$V$27:$V$48,[1]对照表!$X$27:$X$48)),IF(B5="高一",IF($E5="男",LOOKUP(Q5,[1]对照表!$U$3:$U$24,[1]对照表!$X$3:$X$24),LOOKUP(Q5,[1]对照表!$U$27:$U$48,[1]对照表!$X$27:$X$48))))) -> 95 | S5: =ROUND(IF(IF($B5="高三",MIN(IF($E5="男",$Q5-3.2,$Q5-3.2),0),IF($B5="高二",MIN(IF($E5="男",$Q5-3.25,$Q5-3.22),0),IF($B5="高一",MIN(IF($E5="男",$Q5-3.3,$Q5-3.24),0))))<-0.6,IF($B5="高三",MIN(IF($E5="男",$Q5-3.2,$Q5-3.2),0),IF($B5="高二",MIN(IF($E5="男",$Q5-3.25,$Q5-3.22),0),IF($B5="高一",MIN(IF($E5="男",$Q5-3.3,$Q5-3.24),0))))+0.4,IF($B5="高三",MIN(IF($E5="男",$Q5-3.2,$Q5-3.2),0),IF($B5="高二",MIN(IF($E5="男",$Q5-3.25,$Q5-3.22),0),IF($B5="高一",MIN(IF($E5="男",$Q5-3.3,$Q5-3.24),0))))),2) -> 0 | T5: =IF(E5="男",LOOKUP($S5,[1]对照表!$AB$3:$AB$13,[1]对照表!$AC$3:$AC$13),LOOKUP($S5,[1]对照表!$AB$15:$AB$25,[1]对照表!$AC$15:$AC$25)) -> 0 | U5: =R5+T5 -> 95 | V5: =SUM(I5,K5,M5)/3*0.3+SUM(G5,R5)/2*0.4 -> 66.1 | W5: =O5+T5 -> 1 | X5: =V5/0.7+W5 -> 95.428571 | Y5: 95.428571
A6: 34 | B6: 高一 | C6: 101 | D6: 宣东成 | E6: 男 | F6: 7.1 | G6: =IF(B6="高三",IF($E6="男",LOOKUP(F6,[1]对照表!$G$3:$G$24,[1]对照表!$H$3:$H$24),LOOKUP(F6,[1]对照表!$G$27:$G$48,[1]对照表!$H$27:$H$48)),IF(B6="高二",IF($E6="男",LOOKUP(F6,[1]对照表!$F$3:$F$24,[1]对照表!$H$3:$H$24),LOOKUP(F6,[1]对照表!$F$27:$F$48,[1]对照表!$H$27:$H$48)),IF(B6="高一",IF($E6="男",LOOKUP(F6,[1]对照表!$E$3:$E$24,[1]对照表!$H$3:$H$24),LOOKUP(F6,[1]对照表!$E$27:$E$48,[1]对照表!$H$27:$H$48))))) -> 100 | H6: 33.5 | I6: =IF(B6="高三",IF($E6="男",LOOKUP(H6,[1]对照表!$K$3:$K$24,[1]对照表!$L$3:$L$24),LOOKUP(H6,[1]对照表!$K$27:$K$48,[1]对照表!$L$27:$L$48)),IF(B6="高二",IF($E6="男",LOOKUP(H6,[1]对照表!$J$3:$J$24,[1]对照表!$L$3:$L$24),LOOKUP(H6,[1]对照表!$J$27:$J$48,[1]对照表!$L$27:$L$48)),IF(B6="高一",IF($E6="男",LOOKUP(H6,[1]对照表!$I$3:$I$24,[1]对照表!$L$3:$L$24),LOOKUP(H6,[1]对照表!$I$27:$I$48,[1]对照表!$L$27:$L$48))))) -> 100 | J6: 260 | K6: =IF(B6="高三",IF($E6="男",LOOKUP(J6,[1]对照表!$O$3:$O$24,[1]对照表!$P$3:$P$24),LOOKUP(J6,[1]对照表!$O$27:$O$48,[1]对照表!$P$27:$P$48)),IF(B6="高二",IF($E6="男",LOOKUP(J6,[1]对照表!$N$3:$N$24,[1]对照表!$P$3:$P$24),LOOKUP(J6,[1]对照表!$N$27:$N$48,[1]对照表!$P$27:$P$48)),IF(B6="高一",IF($E6="男",LOOKUP(J6,[1]对照表!$M$3:$M$24,[1]对照表!$P$3:$P$24),LOOKUP(J6,[1]对照表!$M$27:$M$48,[1]对照表!$P$27:$P$48))))) -> 100 | L6: 13 | M6: =IF(B6="高三",IF($E6="男",LOOKUP(L6,[1]对照表!$S$3:$S$24,[1]对照表!$T$3:$T$24),LOOKUP(L6,[1]对照表!$S$27:$S$48,[1]对照表!$T$27:$T$48)),IF(B6="高二",IF($E6="男",LOOKUP(L6,[1]对照表!$R$3:$R$24,[1]对照表!$T$3:$T$24),LOOKUP(L6,[1]对照表!$R$27:$R$48,[1]对照表!$T$27:$T$48)),IF(B6="高一",IF($E6="男",LOOKUP(L6,[1]对照表!$Q$3:$Q$24,[1]对照表!$T$3:$T$24),LOOKUP(L6,[1]对照表!$Q$27:$Q$48,[1]对照表!$T$27:$T$48))))) -> 85 | N6: =IF(B6="高三",MAX(IF(E6="男",L6-18,L6-55),0),IF(B6="高二",MAX(IF(E6="男",L6-17,L6-54),0),IF(B6="高一",MAX(IF(E6="男",L6-16,L6-53),0)))) -> 0 | O6: =IF(E6="男",LOOKUP($N6,[1]对照表!$Z$3:$Z$13,[1]对照表!$AA$3:$AA$13),LOOKUP($N6,[1]对照表!$Z$15:$Z$25,[1]对照表!$AA$15:$AA$25)) -> 0 | P6: =M6+O6 -> 85 | Q6: 3.4 | R6: =IF(B6="高三",IF($E6="男",LOOKUP(Q6,[1]对照表!$W$3:$W$24,[1]对照表!$X$3:$X$24),LOOKUP(Q6,[1]对照表!$W$27:$W$48,[1]对照表!$X$27:$X$48)),IF(B6="高二",IF($E6="男",LOOKUP(Q6,[1]对照表!$V$3:$V$24,[1]对照表!$X$3:$X$24),LOOKUP(Q6,[1]对照表!$V$27:$V$48,[1]对照表!$X$27:$X$48)),IF(B6="高一",IF($E6="男",LOOKUP(Q6,[1]对照表!$U$3:$U$24,[1]对照表!$X$3:$X$24),LOOKUP(Q6,[1]对照表!$U$27:$U$48,[1]对照表!$X$27:$X$48))))) -> 90 | S6: =ROUND(IF(IF($B6="高三",MIN(IF($E6="男",$Q6-3.2,$Q6-3.2),0),IF($B6="高二",MIN(IF($E6="男",$Q6-3.25,$Q6-3.22),0),IF($B6="高一",MIN(IF($E6="男",$Q6-3.3,$Q6-3.24),0))))<-0.6,IF($B6="高三",MIN(IF($E6="男",$Q6-3.2,$Q6-3.2),0),IF($B6="高二",MIN(IF($E6="男",$Q6-3.25,$Q6-3.22),0),IF($B6="高一",MIN(IF($E6="男",$Q6-3.3,$Q6-3.24),0))))+0.4,IF($B6="高三",MIN(IF($E6="男",$Q6-3.2,$Q6-3.2),0),IF($B6="高二",MIN(IF($E6="男",$Q6-3.25,$Q6-3.22),0),IF($B6="高一",MIN(IF($E6="男",$Q6-3.3,$Q6-3.24),0))))),2) -> 0 | T6: =IF(E6="男",LOOKUP($S6,[1]对照表!$AB$3:$AB$13,[1]对照表!$AC$3:$AC$13),LOOKUP($S6,[1]对照表!$AB$15:$AB$25,[1]对照表!$AC$15:$AC$25)) -> 0 | U6: =R6+T6 -> 90 | V6: =SUM(I6,K6,M6)/3*0.3+SUM(G6,R6)/2*0.4 -> 66.5 | W6: =O6+T6 -> 0 | X6: =V6/0.7+W6 -> 95 | Y6: 95
A7: 18 | B7: 高一 | C7: 101 | D7: 李奕阳 | E7: 男 | F7: 7 | G7: =IF(B7="高三",IF($E7="男",LOOKUP(F7,[1]对照表!$G$3:$G$24,[1]对照表!$H$3:$H$24),LOOKUP(F7,[1]对照表!$G$27:$G$48,[1]对照表!$H$27:$H$48)),IF(B7="高二",IF($E7="男",LOOKUP(F7,[1]对照表!$F$3:$F$24,[1]对照表!$H$3:$H$24),LOOKUP(F7,[1]对照表!$F$27:$F$48,[1]对照表!$H$27:$H$48)),IF(B7="高一",IF($E7="男",LOOKUP(F7,[1]对照表!$E$3:$E$24,[1]对照表!$H$3:$H$24),LOOKUP(F7,[1]对照表!$E$27:$E$48,[1]对照表!$H$27:$H$48))))) -> 100 | H7: 21.6 | I7: =IF(B7="高三",IF($E7="男",LOOKUP(H7,[1]对照表!$K$3:$K$24,[1]对照表!$L$3:$L$24),LOOKUP(H7,[1]对照表!$K$27:$K$48,[1]对照表!$L$27:$L$48)),IF(B7="高二",IF($E7="男",LOOKUP(H7,[1]对照表!$J$3:$J$24,[1]对照表!$L$3:$L$24),LOOKUP(H7,[1]对照表!$J$27:$J$48,[1]对照表!$L$27:$L$48)),IF(B7="高一",IF($E7="男",LOOKUP(H7,[1]对照表!$I$3:$I$24,[1]对照表!$L$3:$L$24),LOOKUP(H7,[1]对照表!$I$27:$I$48,[1]对照表!$L$27:$L$48))))) -> 95 | J7: 263 | K7: =IF(B7="高三",IF($E7="男",LOOKUP(J7,[1]对照表!$O$3:$O$24,[1]对照表!$P$3:$P$24),LOOKUP(J7,[1]对照表!$O$27:$O$48,[1]对照表!$P$27:$P$48)),IF(B7="高二",IF($E7="男",LOOKUP(J7,[1]对照表!$N$3:$N$24,[1]对照表!$P$3:$P$24),LOOKUP(J7,[1]对照表!$N$27:$N$48,[1]对照表!$P$27:$P$48)),IF(B7="高一",IF($E7="男",LOOKUP(J7,[1]对照表!$M$3:$M$24,[1]对照表!$P$3:$P$24),LOOKUP(J7,[1]对照表!$M$27:$M$48,[1]对照表!$P$27:$P$48))))) -> 100 | L7: 17 | M7: =IF(B7="高三",IF($E7="男",LOOKUP(L7,[1]对照表!$S$3:$S$24,[1]对照表!$T$3:$T$24),LOOKUP(L7,[1]对照表!$S$27:$S$48,[1]对照表!$T$27:$T$48)),IF(B7="高二",IF($E7="男",LOOKUP(L7,[1]对照表!$R$3:$R$24,[1]对照表!$T$3:$T$24),LOOKUP(L7,[1]对照表!$R$27:$R$48,[1]对照表!$T$27:$T$48)),IF(B7="高一",IF($E7="男",LOOKUP(L7,[1]对照表!$Q$3:$Q$24,[1]对照表!$T$3:$T$24),LOOKUP(L7,[1]对照表!$Q$27:$Q$48,[1]对照表!$T$27:$T$48))))) -> 100 | N7: =IF(B7="高三",MAX(IF(E7="男",L7-18,L7-55),0),IF(B7="高二",MAX(IF(E7="男",L7-17,L7-54),0),IF(B7="高一",MAX(IF(E7="男",L7-16,L7-53),0)))) -> 1 | O7: =IF(E7="男",LOOKUP($N7,[1]对照表!$Z$3:$Z$13,[1]对照表!$AA$3:$AA$13),LOOKUP($N7,[1]对照表!$Z$15:$Z$25,[1]对照表!$AA$15:$AA$25)) -> 1 | P7: =M7+O7 -> 101 | Q7: 3.56 | R7: =IF(B7="高三",IF($E7="男",LOOKUP(Q7,[1]对照表!$W$3:$W$24,[1]对照表!$X$3:$X$24),LOOKUP(Q7,[1]对照表!$W$27:$W$48,[1]对照表!$X$27:$X$48)),IF(B7="高二",IF($E7="男",LOOKUP(Q7,[1]对照表!$V$3:$V$24,[1]对照表!$X$3:$X$24),LOOKUP(Q7,[1]对照表!$V$27:$V$48,[1]对照表!$X$27:$X$48)),IF(B7="高一",IF($E7="男",LOOKUP(Q7,[1]对照表!$U$3:$U$24,[1]对照表!$X$3:$X$24),LOOKUP(Q7,[1]对照表!$U$27:$U$48,[1]对照表!$X$27:$X$48))))) -> 78 | S7: =ROUND(IF(IF($B7="高三",MIN(IF($E7="男",$Q7-3.2,$Q7-3.2),0),IF($B7="高二",MIN(IF($E7="男",$Q7-3.25,$Q7-3.22),0),IF($B7="高一",MIN(IF($E7="男",$Q7-3.3,$Q7-3.24),0))))<-0.6,IF($B7="高三",MIN(IF($E7="男",$Q7-3.2,$Q7-3.2),0),IF($B7="高二",MIN(IF($E7="男",$Q7-3.25,$Q7-3.22),0),IF($B7="高一",MIN(IF($E7="男",$Q7-3.3,$Q7-3.24),0))))+0.4,IF($B7="高三",MIN(IF($E7="男",$Q7-3.2,$Q7-3.2),0),IF($B7="高二",MIN(IF($E7="男",$Q7-3.25,$Q7-3.22),0),IF($B7="高一",MIN(IF($E7="男",$Q7-3.3,$Q7-3.24),0))))),2) -> 0 | T7: =IF(E7="男",LOOKUP($S7,[1]对照表!$AB$3:$AB$13,[1]对照表!$AC$3:$AC$13),LOOKUP($S7,[1]对照表!$AB$15:$AB$25,[1]对照表!$AC$15:$AC$25)) -> 0 | U7: =R7+T7 -> 78 | V7: =SUM(I7,K7,M7)/3*0.3+SUM(G7,R7)/2*0.4 -> 65.1 | W7: =O7+T7 -> 1 | X7: =V7/0.7+W7 -> 94 | Y7: 94
A8: 16 | B8: 高一 | C8: 101 | D8: 李亮熙 | E8: 男 | F8: 7.2 | G8: =IF(B8="高三",IF($E8="男",LOOKUP(F8,[1]对照表!$G$3:$G$24,[1]对照表!$H$3:$H$24),LOOKUP(F8,[1]对照表!$G$27:$G$48,[1]对照表!$H$27:$H$48)),IF(B8="高二",IF($E8="男",LOOKUP(F8,[1]对照表!$F$3:$F$24,[1]对照表!$H$3:$H$24),LOOKUP(F8,[1]对照表!$F$27:$F$48,[1]对照表!$H$27:$H$48)),IF(B8="高一",IF($E8="男",LOOKUP(F8,[1]对照表!$E$3:$E$24,[1]对照表!$H$3:$H$24),LOOKUP(F8,[1]对照表!$E$27:$E$48,[1]对照表!$H$27:$H$48))))) -> 95 | H8: 31.5 | I8: =IF(B8="高三",IF($E8="男",LOOKUP(H8,[1]对照表!$K$3:$K$24,[1]对照表!$L$3:$L$24),LOOKUP(H8,[1]对照表!$K$27:$K$48,[1]对照表!$L$27:$L$48)),IF(B8="高二",IF($E8="男",LOOKUP(H8,[1]对照表!$J$3:$J$24,[1]对照表!$L$3:$L$24),LOOKUP(H8,[1]对照表!$J$27:$J$48,[1]对照表!$L$27:$L$48)),IF(B8="高一",IF($E8="男",LOOKUP(H8,[1]对照表!$I$3:$I$24,[1]对照表!$L$3:$L$24),LOOKUP(H8,[1]对照表!$I$27:$I$48,[1]对照表!$L$27:$L$48))))) -> 100 | J8: 246 | K8: =IF(B8="高三",IF($E8="男",LOOKUP(J8,[1]对照表!$O$3:$O$24,[1]对照表!$P$3:$P$24),LOOKUP(J8,[1]对照表!$O$27:$O$48,[1]对照表!$P$27:$P$48)),IF(B8="高二",IF($E8="男",LOOKUP(J8,[1]对照表!$N$3:$N$24,[1]对照表!$P$3:$P$24),LOOKUP(J8,[1]对照表!$N$27:$N$48,[1]对照表!$P$27:$P$48)),IF(B8="高一",IF($E8="男",LOOKUP(J8,[1]对照表!$M$3:$M$24,[1]对照表!$P$3:$P$24),LOOKUP(J8,[1]对照表!$M$27:$M$48,[1]对照表!$P$27:$P$48))))) -> 85 | L8: 9 | M8: =IF(B8="高三",IF($E8="男",LOOKUP(L8,[1]对照表!$S$3:$S$24,[1]对照表!$T$3:$T$24),LOOKUP(L8,[1]对照表!$S$27:$S$48,[1]对照表!$T$27:$T$48)),IF(B8="高二",IF($E8="男",LOOKUP(L8,[1]对照表!$R$3:$R$24,[1]对照表!$T$3:$T$24),LOOKUP(L8,[1]对照表!$R$27:$R$48,[1]对照表!$T$27:$T$48)),IF(B8="高一",IF($E8="男",LOOKUP(L8,[1]对照表!$Q$3:$Q$24,[1]对照表!$T$3:$T$24),LOOKUP(L8,[1]对照表!$Q$27:$Q$48,[1]对照表!$T$27:$T$48))))) -> 68 | N8: =IF(B8="高三",MAX(IF(E8="男",L8-18,L8-55),0),IF(B8="高二",MAX(IF(E8="男",L8-17,L8-54),0),IF(B8="高一",MAX(IF(E8="男",L8-16,L8-53),0)))) -> 0 | O8: =IF(E8="男",LOOKUP($N8,[1]对照表!$Z$3:$Z$13,[1]对照表!$AA$3:$AA$13),LOOKUP($N8,[1]对照表!$Z$15:$Z$25,[1]对照表!$AA$15:$AA$25)) -> 0 | P8: =M8+O8 -> 68 | Q8: 3.28 | R8: =IF(B8="高三",IF($E8="男",LOOKUP(Q8,[1]对照表!$W$3:$W$24,[1]对照表!$X$3:$X$24),LOOKUP(Q8,[1]对照表!$W$27:$W$48,[1]对照表!$X$27:$X$48)),IF(B8="高二",IF($E8="男",LOOKUP(Q8,[1]对照表!$V$3:$V$24,[1]对照表!$X$3:$X$24),LOOKUP(Q8,[1]对照表!$V$27:$V$48,[1]对照表!$X$27:$X$48)),IF(B8="高一",IF($E8="男",LOOKUP(Q8,[1]对照表!$U$3:$U$24,[1]对照表!$X$3:$X$24),LOOKUP(Q8,[1]对照表!$U$27:$U$48,[1]对照表!$X$27:$X$48))))) -> 100 | S8: =ROUND(IF(IF($B8="高三",MIN(IF($E8="男",$Q8-3.2,$Q8-3.2),0),IF($B8="高二",MIN(IF($E8="男",$Q8-3.25,$Q8-3.22),0),IF($B8="高一",MIN(IF($E8="男",$Q8-3.3,$Q8-3.24),0))))<-0.6,IF($B8="高三",MIN(IF($E8="男",$Q8-3.2,$Q8-3.2),0),IF($B8="高二",MIN(IF($E8="男",$Q8-3.25,$Q8-3.22),0),IF($B8="高一",MIN(IF($E8="男",$Q8-3.3,$Q8-3.24),0))))+0.4,IF($B8="高三",MIN(IF($E8="男",$Q8-3.2,$Q8-3.2),0),IF($B8="高二",MIN(IF($E8="男",$Q8-3.25,$Q8-3.22),0),IF($B8="高一",MIN(IF($E8="男",$Q8-3.3,$Q8-3.24),0))))),2) -> -0.02 | T8: =IF(E8="男",LOOKUP($S8,[1]对照表!$AB$3:$AB$13,[1]对照表!$AC$3:$AC$13),LOOKUP($S8,[1]对照表!$AB$15:$AB$25,[1]对照表!$AC$15:$AC$25)) -> 0 | U8: =R8+T8 -> 100 | V8: =SUM(I8,K8,M8)/3*0.3+SUM(G8,R8)/2*0.4 -> 64.3 | W8: =O8+T8 -> 0 | X8: =V8/0.7+W8 -> 91.857143 | Y8: 91.857143
A9: 38 | B9: 高一 | C9: 101 | D9: 朱皓瀛 | E9: 男 | F9: 7.1 | G9: =IF(B9="高三",IF($E9="男",LOOKUP(F9,[1]对照表!$G$3:$G$24,[1]对照表!$H$3:$H$24),LOOKUP(F9,[1]对照表!$G$27:$G$48,[1]对照表!$H$27:$H$48)),IF(B9="高二",IF($E9="男",LOOKUP(F9,[1]对照表!$F$3:$F$24,[1]对照表!$H$3:$H$24),LOOKUP(F9,[1]对照表!$F$27:$F$48,[1]对照表!$H$27:$H$48)),IF(B9="高一",IF($E9="男",LOOKUP(F9,[1]对照表!$E$3:$E$24,[1]对照表!$H$3:$H$24),LOOKUP(F9,[1]对照表!$E$27:$E$48,[1]对照表!$H$27:$H$48))))) -> 100 | H9: 15.5 | I9: =IF(B9="高三",IF($E9="男",LOOKUP(H9,[1]对照表!$K$3:$K$24,[1]对照表!$L$3:$L$24),LOOKUP(H9,[1]对照表!$K$27:$K$48,[1]对照表!$L$27:$L$48)),IF(B9="高二",IF($E9="男",LOOKUP(H9,[1]对照表!$J$3:$J$24,[1]对照表!$L$3:$L$24),LOOKUP(H9,[1]对照表!$J$27:$J$48,[1]对照表!$L$27:$L$48)),IF(B9="高一",IF($E9="男",LOOKUP(H9,[1]对照表!$I$3:$I$24,[1]对照表!$L$3:$L$24),LOOKUP(H9,[1]对照表!$I$27:$I$48,[1]对照表!$L$27:$L$48))))) -> 80 | J9: 228 | K9: =IF(B9="高三",IF($E9="男",LOOKUP(J9,[1]对照表!$O$3:$O$24,[1]对照表!$P$3:$P$24),LOOKUP(J9,[1]对照表!$O$27:$O$48,[1]对照表!$P$27:$P$48)),IF(B9="高二",IF($E9="男",LOOKUP(J9,[1]对照表!$N$3:$N$24,[1]对照表!$P$3:$P$24),LOOKUP(J9,[1]对照表!$N$27:$N$48,[1]对照表!$P$27:$P$48)),IF(B9="高一",IF($E9="男",LOOKUP(J9,[1]对照表!$M$3:$M$24,[1]对照表!$P$3:$P$24),LOOKUP(J9,[1]对照表!$M$27:$M$48,[1]对照表!$P$27:$P$48))))) -> 76 | L9: 17 | M9: =IF(B9="高三",IF($E9="男",LOOKUP(L9,[1]对照表!$S$3:$S$24,[1]对照表!$T$3:$T$24),LOOKUP(L9,[1]对照表!$S$27:$S$48,[1]对照表!$T$27:$T$48)),IF(B9="高二",IF($E9="男",LOOKUP(L9,[1]对照表!$R$3:$R$24,[1]对照表!$T$3:$T$24),LOOKUP(L9,[1]对照表!$R$27:$R$48,[1]对照表!$T$27:$T$48)),IF(B9="高一",IF($E9="男",LOOKUP(L9,[1]对照表!$Q$3:$Q$24,[1]对照表!$T$3:$T$24),LOOKUP(L9,[1]对照表!$Q$27:$Q$48,[1]对照表!$T$27:$T$48))))) -> 100 | N9: =IF(B9="高三",MAX(IF(E9="男",L9-18,L9-55),0),IF(B9="高二",MAX(IF(E9="男",L9-17,L9-54),0),IF(B9="高一",MAX(IF(E9="男",L9-16,L9-53),0)))) -> 1 | O9: =IF(E9="男",LOOKUP($N9,[1]对照表!$Z$3:$Z$13,[1]对照表!$AA$3:$AA$13),LOOKUP($N9,[1]对照表!$Z$15:$Z$25,[1]对照表!$AA$15:$AA$25)) -> 1 | P9: =M9+O9 -> 101 | Q9: 3.41 | R9: =IF(B9="高三",IF($E9="男",LOOKUP(Q9,[1]对照表!$W$3:$W$24,[1]对照表!$X$3:$X$24),LOOKUP(Q9,[1]对照表!$W$27:$W$48,[1]对照表!$X$27:$X$48)),IF(B9="高二",IF($E9="男",LOOKUP(Q9,[1]对照表!$V$3:$V$24,[1]对照表!$X$3:$X$24),LOOKUP(Q9,[1]对照表!$V$27:$V$48,[1]对照表!$X$27:$X$48)),IF(B9="高一",IF($E9="男",LOOKUP(Q9,[1]对照表!$U$3:$U$24,[1]对照表!$X$3:$X$24),LOOKUP(Q9,[1]对照表!$U$27:$U$48,[1]对照表!$X$27:$X$48))))) -> 85 | S9: =ROUND(IF(IF($B9="高三",MIN(IF($E9="男",$Q9-3.2,$Q9-3.2),0),IF($B9="高二",MIN(IF($E9="男",$Q9-3.25,$Q9-3.22),0),IF($B9="高一",MIN(IF($E9="男",$Q9-3.3,$Q9-3.24),0))))<-0.6,IF($B9="高三",MIN(IF($E9="男",$Q9-3.2,$Q9-3.2),0),IF($B9="高二",MIN(IF($E9="男",$Q9-3.25,$Q9-3.22),0),IF($B9="高一",MIN(IF($E9="男",$Q9-3.3,$Q9-3.24),0))))+0.4,IF($B9="高三",MIN(IF($E9="男",$Q9-3.2,$Q9-3.2),0),IF($B9="高二",MIN(IF($E9="男",$Q9-3.25,$Q9-3.22),0),IF($B9="高一",MIN(IF($E9="男",$Q9-3.3,$Q9-3.24),0))))),2) -> 0 | T9: =IF(E9="男",LOOKUP($S9,[1]对照表!$AB$3:$AB$13,[1]对照表!$AC$3:$AC$13),LOOKUP($S9,[1]对照表!$AB$15:$AB$25,[1]对照表!$AC$15:$AC$25)) -> 0 | U9: =R9+T9 -> 85 | V9: =SUM(I9,K9,M9)/3*0.3+SUM(G9,R9)/2*0.4 -> 62.6 | W9: =O9+T9 -> 1 | X9: =V9/0.7+W9 -> 90.428571 | Y9: 90.428571
A10: 4 | B10: 高一 | C10: 101 | D10: 陈科嘉 | E10: 男 | F10: 7.2 | G10: =IF(B10="高三",IF($E10="男",LOOKUP(F10,[1]对照表!$G$3:$G$24,[1]对照表!$H$3:$H$24),LOOKUP(F10,[1]对照表!$G$27:$G$48,[1]对照表!$H$27:$H$48)),IF(B10="高二",IF($E10="男",LOOKUP(F10,[1]对照表!$F$3:$F$24,[1]对照表!$H$3:$H$24),LOOKUP(F10,[1]对照表!$F$27:$F$48,[1]对照表!$H$27:$H$48)),IF(B10="高一",IF($E10="男",LOOKUP(F10,[1]对照表!$E$3:$E$24,[1]对照表!$H$3:$H$24),LOOKUP(F10,[1]对照表!$E$27:$E$48,[1]对照表!$H$27:$H$48))))) -> 95 | H10: 3.1 | I10: =IF(B10="高三",IF($E10="男",LOOKUP(H10,[1]对照表!$K$3:$K$24,[1]对照表!$L$3:$L$24),LOOKUP(H10,[1]对照表!$K$27:$K$48,[1]对照表!$L$27:$L$48)),IF(B10="高二",IF($E10="男",LOOKUP(H10,[1]对照表!$J$3:$J$24,[1]对照表!$L$3:$L$24),LOOKUP(H10,[1]对照表!$J$27:$J$48,[1]对照表!$L$27:$L$48)),IF(B10="高一",IF($E10="男",LOOKUP(H10,[1]对照表!$I$3:$I$24,[1]对照表!$L$3:$L$24),LOOKUP(H10,[1]对照表!$I$27:$I$48,[1]对照表!$L$27:$L$48))))) -> 62 | J10: 238 | K10: =IF(B10="高三",IF($E10="男",LOOKUP(J10,[1]对照表!$O$3:$O$24,[1]对照表!$P$3:$P$24),LOOKUP(J10,[1]对照表!$O$27:$O$48,[1]对照表!$P$27:$P$48)),IF(B10="高二",IF($E10="男",LOOKUP(J10,[1]对照表!$N$3:$N$24,[1]对照表!$P$3:$P$24),LOOKUP(J10,[1]对照表!$N$27:$N$48,[1]对照表!$P$27:$P$48)),IF(B10="高一",IF($E10="男",LOOKUP(J10,[1]对照表!$M$3:$M$24,[1]对照表!$P$3:$P$24),LOOKUP(J10,[1]对照表!$M$27:$M$48,[1]对照表!$P$27:$P$48))))) -> 80 | L10: 20 | M10: =IF(B10="高三",IF($E10="男",LOOKUP(L10,[1]对照表!$S$3:$S$24,[1]对照表!$T$3:$T$24),LOOKUP(L10,[1]对照表!$S$27:$S$48,[1]对照表!$T$27:$T$48)),IF(B10="高二",IF($E10="男",LOOKUP(L10,[1]对照表!$R$3:$R$24,[1]对照表!$T$3:$T$24),LOOKUP(L10,[1]对照表!$R$27:$R$48,[1]对照表!$T$27:$T$48)),IF(B10="高一",IF($E10="男",LOOKUP(L10,[1]对照表!$Q$3:$Q$24,[1]对照表!$T$3:$T$24),LOOKUP(L10,[1]对照表!$Q$27:$Q$48,[1]对照表!$T$27:$T$48))))) -> 100 | N10: =IF(B10="高三",MAX(IF(E10="男",L10-18,L10-55),0),IF(B10="高二",MAX(IF(E10="男",L10-17,L10-54),0),IF(B10="高一",MAX(IF(E10="男",L10-16,L10-53),0)))) -> 4 | O10: =IF(E10="男",LOOKUP($N10,[1]对照表!$Z$3:$Z$13,[1]对照表!$AA$3:$AA$13),LOOKUP($N10,[1]对照表!$Z$15:$Z$25,[1]对照表!$AA$15:$AA$25)) -> 4 | P10: =M10+O10 -> 104 | Q10: 3.46 | R10: =IF(B10="高三",IF($E10="男",LOOKUP(Q10,[1]对照表!$W$3:$W$24,[1]对照表!$X$3:$X$24),LOOKUP(Q10,[1]对照表!$W$27:$W$48,[1]对照表!$X$27:$X$48)),IF(B10="高二",IF($E10="男",LOOKUP(Q10,[1]对照表!$V$3:$V$24,[1]对照表!$X$3:$X$24),LOOKUP(Q10,[1]对照表!$V$27:$V$48,[1]对照表!$X$27:$X$48)),IF(B10="高一",IF($E10="男",LOOKUP(Q10,[1]对照表!$U$3:$U$24,[1]对照表!$X$3:$X$24),LOOKUP(Q10,[1]对照表!$U$27:$U$48,[1]对照表!$X$27:$X$48))))) -> 85 | S10: =ROUND(IF(IF($B10="高三",MIN(IF($E10="男",$Q10-3.2,$Q10-3.2),0),IF($B10="高二",MIN(IF($E10="男",$Q10-3.25,$Q10-3.22),0),IF($B10="高一",MIN(IF($E10="男",$Q10-3.3,$Q10-3.24),0))))<-0.6,IF($B10="高三",MIN(IF($E10="男",$Q10-3.2,$Q10-3.2),0),IF($B10="高二",MIN(IF($E10="男",$Q10-3.25,$Q10-3.22),0),IF($B10="高一",MIN(IF($E10="男",$Q10-3.3,$Q10-3.24),0))))+0.4,IF($B10="高三",MIN(IF($E10="男",$Q10-3.2,$Q10-3.2),0),IF($B10="高二",MIN(IF($E10="男",$Q10-3.25,$Q10-3.22),0),IF($B10="高一",MIN(IF($E10="男",$Q10-3.3,$Q10-3.24),0))))),2) -> 0 | T10: =IF(E10="男",LOOKUP($S10,[1]对照表!$AB$3:$AB$13,[1]对照表!$AC$3:$AC$13),LOOKUP($S10,[1]对照表!$AB$15:$AB$25,[1]对照表!$AC$15:$AC$25)) -> 0 | U10: =R10+T10 -> 85 | V10: =SUM(I10,K10,M10)/3*0.3+SUM(G10,R10)/2*0.4 -> 60.2 | W10: =O10+T10 -> 4 | X10: =V10/0.7+W10 -> 90 | Y10: 90
A11: 9 | B11: 高一 | C11: 101 | D11: 付杨帆 | E11: 男 | F11: 7.1 | G11: =IF(B11="高三",IF($E11="男",LOOKUP(F11,[1]对照表!$G$3:$G$24,[1]对照表!$H$3:$H$24),LOOKUP(F11,[1]对照表!$G$27:$G$48,[1]对照表!$H$27:$H$48)),IF(B11="高二",IF($E11="男",LOOKUP(F11,[1]对照表!$F$3:$F$24,[1]对照表!$H$3:$H$24),LOOKUP(F11,[1]对照表!$F$27:$F$48,[1]对照表!$H$27:$H$48)),IF(B11="高一",IF($E11="男",LOOKUP(F11,[1]对照表!$E$3:$E$24,[1]对照表!$H$3:$H$24),LOOKUP(F11,[1]对照表!$E$27:$E$48,[1]对照表!$H$27:$H$48))))) -> 100 | H11: 2.8 | I11: =IF(B11="高三",IF($E11="男",LOOKUP(H11,[1]对照表!$K$3:$K$24,[1]对照表!$L$3:$L$24),LOOKUP(H11,[1]对照表!$K$27:$K$48,[1]对照表!$L$27:$L$48)),IF(B11="高二",IF($E11="男",LOOKUP(H11,[1]对照表!$J$3:$J$24,[1]对照表!$L$3:$L$24),LOOKUP(H11,[1]对照表!$J$27:$J$48,[1]对照表!$L$27:$L$48)),IF(B11="高一",IF($E11="男",LOOKUP(H11,[1]对照表!$I$3:$I$24,[1]对照表!$L$3:$L$24),LOOKUP(H11,[1]对照表!$I$27:$I$48,[1]对照表!$L$27:$L$48))))) -> 62 | J11: 236 | K11: =IF(B11="高三",IF($E11="男",LOOKUP(J11,[1]对照表!$O$3:$O$24,[1]对照表!$P$3:$P$24),LOOKUP(J11,[1]对照表!$O$27:$O$48,[1]对照表!$P$27:$P$48)),IF(B11="高二",IF($E11="男",LOOKUP(J11,[1]对照表!$N$3:$N$24,[1]对照表!$P$3:$P$24),LOOKUP(J11,[1]对照表!$N$27:$N$48,[1]对照表!$P$27:$P$48)),IF(B11="高一",IF($E11="男",LOOKUP(J11,[1]对照表!$M$3:$M$24,[1]对照表!$P$3:$P$24),LOOKUP(J11,[1]对照表!$M$27:$M$48,[1]对照表!$P$27:$P$48))))) -> 80 | L11: 15 | M11: =IF(B11="高三",IF($E11="男",LOOKUP(L11,[1]对照表!$S$3:$S$24,[1]对照表!$T$3:$T$24),LOOKUP(L11,[1]对照表!$S$27:$S$48,[1]对照表!$T$27:$T$48)),IF(B11="高二",IF($E11="男",LOOKUP(L11,[1]对照表!$R$3:$R$24,[1]对照表!$T$3:$T$24),LOOKUP(L11,[1]对照表!$R$27:$R$48,[1]对照表!$T$27:$T$48)),IF(B11="高一",IF($E11="男",LOOKUP(L11,[1]对照表!$Q$3:$Q$24,[1]对照表!$T$3:$T$24),LOOKUP(L11,[1]对照表!$Q$27:$Q$48,[1]对照表!$T$27:$T$48))))) -> 95 | N11: =IF(B11="高三",MAX(IF(E11="男",L11-18,L11-55),0),IF(B11="高二",MAX(IF(E11="男",L11-17,L11-54),0),IF(B11="高一",MAX(IF(E11="男",L11-16,L11-53),0)))) -> 0 | O11: =IF(E11="男",LOOKUP($N11,[1]对照表!$Z$3:$Z$13,[1]对照表!$AA$3:$AA$13),LOOKUP($N11,[1]对照表!$Z$15:$Z$25,[1]对照表!$AA$15:$AA$25)) -> 0 | P11: =M11+O11 -> 95 | Q11: 3.31 | R11: =IF(B11="高三",IF($E11="男",LOOKUP(Q11,[1]对照表!$W$3:$W$24,[1]对照表!$X$3:$X$24),LOOKUP(Q11,[1]对照表!$W$27:$W$48,[1]对照表!$X$27:$X$48)),IF(B11="高二",IF($E11="男",LOOKUP(Q11,[1]对照表!$V$3:$V$24,[1]对照表!$X$3:$X$24),LOOKUP(Q11,[1]对照表!$V$27:$V$48,[1]对照表!$X$27:$X$48)),IF(B11="高一",IF($E11="男",LOOKUP(Q11,[1]对照表!$U$3:$U$24,[1]对照表!$X$3:$X$24),LOOKUP(Q11,[1]对照表!$U$27:$U$48,[1]对照表!$X$27:$X$48))))) -> 95 | S11: =ROUND(IF(IF($B11="高三",MIN(IF($E11="男",$Q11-3.2,$Q11-3.2),0),IF($B11="高二",MIN(IF($E11="男",$Q11-3.25,$Q11-3.22),0),IF($B11="高一",MIN(IF($E11="男",$Q11-3.3,$Q11-3.24),0))))<-0.6,IF($B11="高三",MIN(IF($E11="男",$Q11-3.2,$Q11-3.2),0),IF($B11="高二",MIN(IF($E11="男",$Q11-3.25,$Q11-3.22),0),IF($B11="高一",MIN(IF($E11="男",$Q11-3.3,$Q11-3.24),0))))+0.4,IF($B11="高三",MIN(IF($E11="男",$Q11-3.2,$Q11-3.2),0),IF($B11="高二",MIN(IF($E11="男",$Q11-3.25,$Q11-3.22),0),IF($B11="高一",MIN(IF($E11="男",$Q11-3.3,$Q11-3.24),0))))),2) -> 0 | T11: =IF(E11="男",LOOKUP($S11,[1]对照表!$AB$3:$AB$13,[1]对照表!$AC$3:$AC$13),LOOKUP($S11,[1]对照表!$AB$15:$AB$25,[1]对照表!$AC$15:$AC$25)) -> 0 | U11: =R11+T11 -> 95 | V11: =SUM(I11,K11,M11)/3*0.3+SUM(G11,R11)/2*0.4 -> 62.7 | W11: =O11+T11 -> 0 | X11: =V11/0.7+W11 -> 89.571429 | Y11: 89.571429
A12: 40 | B12: 高一 | C12: 101 | D12: 朱屹茗 | E12: 男 | F12: 7 | G12: =IF(B12="高三",IF($E12="男",LOOKUP(F12,[1]对照表!$G$3:$G$24,[1]对照表!$H$3:$H$24),LOOKUP(F12,[1]对照表!$G$27:$G$48,[1]对照表!$H$27:$H$48)),IF(B12="高二",IF($E12="男",LOOKUP(F12,[1]对照表!$F$3:$F$24,[1]对照表!$H$3:$H$24),LOOKUP(F12,[1]对照表!$F$27:$F$48,[1]对照表!$H$27:$H$48)),IF(B12="高一",IF($E12="男",LOOKUP(F12,[1]对照表!$E$3:$E$24,[1]对照表!$H$3:$H$24),LOOKUP(F12,[1]对照表!$E$27:$E$48,[1]对照表!$H$27:$H$48))))) -> 100 | H12: 8 | I12: =IF(B12="高三",IF($E12="男",LOOKUP(H12,[1]对照表!$K$3:$K$24,[1]对照表!$L$3:$L$24),LOOKUP(H12,[1]对照表!$K$27:$K$48,[1]对照表!$L$27:$L$48)),IF(B12="高二",IF($E12="男",LOOKUP(H12,[1]对照表!$J$3:$J$24,[1]对照表!$L$3:$L$24),LOOKUP(H12,[1]对照表!$J$27:$J$48,[1]对照表!$L$27:$L$48)),IF(B12="高一",IF($E12="男",LOOKUP(H12,[1]对照表!$I$3:$I$24,[1]对照表!$L$3:$L$24),LOOKUP(H12,[1]对照表!$I$27:$I$48,[1]对照表!$L$27:$L$48))))) -> 70 | J12: 230 | K12: =IF(B12="高三",IF($E12="男",LOOKUP(J12,[1]对照表!$O$3:$O$24,[1]对照表!$P$3:$P$24),LOOKUP(J12,[1]对照表!$O$27:$O$48,[1]对照表!$P$27:$P$48)),IF(B12="高二",IF($E12="男",LOOKUP(J12,[1]对照表!$N$3:$N$24,[1]对照表!$P$3:$P$24),LOOKUP(J12,[1]对照表!$N$27:$N$48,[1]对照表!$P$27:$P$48)),IF(B12="高一",IF($E12="男",LOOKUP(J12,[1]对照表!$M$3:$M$24,[1]对照表!$P$3:$P$24),LOOKUP(J12,[1]对照表!$M$27:$M$48,[1]对照表!$P$27:$P$48))))) -> 76 | L12: 14 | M12: =IF(B12="高三",IF($E12="男",LOOKUP(L12,[1]对照表!$S$3:$S$24,[1]对照表!$T$3:$T$24),LOOKUP(L12,[1]对照表!$S$27:$S$48,[1]对照表!$T$27:$T$48)),IF(B12="高二",IF($E12="男",LOOKUP(L12,[1]对照表!$R$3:$R$24,[1]对照表!$T$3:$T$24),LOOKUP(L12,[1]对照表!$R$27:$R$48,[1]对照表!$T$27:$T$48)),IF(B12="高一",IF($E12="男",LOOKUP(L12,[1]对照表!$Q$3:$Q$24,[1]对照表!$T$3:$T$24),LOOKUP(L12,[1]对照表!$Q$27:$Q$48,[1]对照表!$T$27:$T$48))))) -> 90 | N12: =IF(B12="高三",MAX(IF(E12="男",L12-18,L12-55),0),IF(B12="高二",MAX(IF(E12="男",L12-17,L12-54),0),IF(B12="高一",MAX(IF(E12="男",L12-16,L12-53),0)))) -> 0 | O12: =IF(E12="男",LOOKUP($N12,[1]对照表!$Z$3:$Z$13,[1]对照表!$AA$3:$AA$13),LOOKUP($N12,[1]对照表!$Z$15:$Z$25,[1]对照表!$AA$15:$AA$25)) -> 0 | P12: =M12+O12 -> 90 | Q12: 3.4 | R12: =IF(B12="高三",IF($E12="男",LOOKUP(Q12,[1]对照表!$W$3:$W$24,[1]对照表!$X$3:$X$24),LOOKUP(Q12,[1]对照表!$W$27:$W$48,[1]对照表!$X$27:$X$48)),IF(B12="高二",IF($E12="男",LOOKUP(Q12,[1]对照表!$V$3:$V$24,[1]对照表!$X$3:$X$24),LOOKUP(Q12,[1]对照表!$V$27:$V$48,[1]对照表!$X$27:$X$48)),IF(B12="高一",IF($E12="男",LOOKUP(Q12,[1]对照表!$U$3:$U$24,[1]对照表!$X$3:$X$24),LOOKUP(Q12,[1]对照表!$U$27:$U$48,[1]对照表!$X$27:$X$48))))) -> 90 | S12: =ROUND(IF(IF($B12="高三",MIN(IF($E12="男",$Q12-3.2,$Q12-3.2),0),IF($B12="高二",MIN(IF($E12="男",$Q12-3.25,$Q12-3.22),0),IF($B12="高一",MIN(IF($E12="男",$Q12-3.3,$Q12-3.24),0))))<-0.6,IF($B12="高三",MIN(IF($E12="男",$Q12-3.2,$Q12-3.2),0),IF($B12="高二",MIN(IF($E12="男",$Q12-3.25,$Q12-3.22),0),IF($B12="高一",MIN(IF($E12="男",$Q12-3.3,$Q12-3.24),0))))+0.4,IF($B12="高三",MIN(IF($E12="男",$Q12-3.2,$Q12-3.2),0),IF($B12="高二",MIN(IF($E12="男",$Q12-3.25,$Q12-3.22),0),IF($B12="高一",MIN(IF($E12="男",$Q12-3.3,$Q12-3.24),0))))),2) -> 0 | T12: =IF(E12="男",LOOKUP($S12,[1]对照表!$AB$3:$AB$13,[1]对照表!$AC$3:$AC$13),LOOKUP($S12,[1]对照表!$AB$15:$AB$25,[1]对照表!$AC$15:$AC$25)) -> 0 | U12: =R12+T12 -> 90 | V12: =SUM(I12,K12,M12)/3*0.3+SUM(G12,R12)/2*0.4 -> 61.6 | W12: =O12+T12 -> 0 | X12: =V12/0.7+W12 -> 88 | Y12: 88
A13: 26 | B13: 高一 | C13: 101 | D13: 任浩轩 | E13: 男 | F13: 7.1 | G13: =IF(B13="高三",IF($E13="男",LOOKUP(F13,[1]对照表!$G$3:$G$24,[1]对照表!$H$3:$H$24),LOOKUP(F13,[1]对照表!$G$27:$G$48,[1]对照表!$H$27:$H$48)),IF(B13="高二",IF($E13="男",LOOKUP(F13,[1]对照表!$F$3:$F$24,[1]对照表!$H$3:$H$24),LOOKUP(F13,[1]对照表!$F$27:$F$48,[1]对照表!$H$27:$H$48)),IF(B13="高一",IF($E13="男",LOOKUP(F13,[1]对照表!$E$3:$E$24,[1]对照表!$H$3:$H$24),LOOKUP(F13,[1]对照表!$E$27:$E$48,[1]对照表!$H$27:$H$48))))) -> 100 | H13: 12 | I13: =IF(B13="高三",IF($E13="男",LOOKUP(H13,[1]对照表!$K$3:$K$24,[1]对照表!$L$3:$L$24),LOOKUP(H13,[1]对照表!$K$27:$K$48,[1]对照表!$L$27:$L$48)),IF(B13="高二",IF($E13="男",LOOKUP(H13,[1]对照表!$J$3:$J$24,[1]对照表!$L$3:$L$24),LOOKUP(H13,[1]对照表!$J$27:$J$48,[1]对照表!$L$27:$L$48)),IF(B13="高一",IF($E13="男",LOOKUP(H13,[1]对照表!$I$3:$I$24,[1]对照表!$L$3:$L$24),LOOKUP(H13,[1]对照表!$I$27:$I$48,[1]对照表!$L$27:$L$48))))) -> 74 | J13: 210 | K13: =IF(B13="高三",IF($E13="男",LOOKUP(J13,[1]对照表!$O$3:$O$24,[1]对照表!$P$3:$P$24),LOOKUP(J13,[1]对照表!$O$27:$O$48,[1]对照表!$P$27:$P$48)),IF(B13="高二",IF($E13="男",LOOKUP(J13,[1]对照表!$N$3:$N$24,[1]对照表!$P$3:$P$24),LOOKUP(J13,[1]对照表!$N$27:$N$48,[1]对照表!$P$27:$P$48)),IF(B13="高一",IF($E13="男",LOOKUP(J13,[1]对照表!$M$3:$M$24,[1]对照表!$P$3:$P$24),LOOKUP(J13,[1]对照表!$M$27:$M$48,[1]对照表!$P$27:$P$48))))) -> 66 | L13: 9 | M13: =IF(B13="高三",IF($E13="男",LOOKUP(L13,[1]对照表!$S$3:$S$24,[1]对照表!$T$3:$T$24),LOOKUP(L13,[1]对照表!$S$27:$S$48,[1]对照表!$T$27:$T$48)),IF(B13="高二",IF($E13="男",LOOKUP(L13,[1]对照表!$R$3:$R$24,[1]对照表!$T$3:$T$24),LOOKUP(L13,[1]对照表!$R$27:$R$48,[1]对照表!$T$27:$T$48)),IF(B13="高一",IF($E13="男",LOOKUP(L13,[1]对照表!$Q$3:$Q$24,[1]对照表!$T$3:$T$24),LOOKUP(L13,[1]对照表!$Q$27:$Q$48,[1]对照表!$T$27:$T$48))))) -> 68 | N13: =IF(B13="高三",MAX(IF(E13="男",L13-18,L13-55),0),IF(B13="高二",MAX(IF(E13="男",L13-17,L13-54),0),IF(B13="高一",MAX(IF(E13="男",L13-16,L13-53),0)))) -> 0 | O13: =IF(E13="男",LOOKUP($N13,[1]对照表!$Z$3:$Z$13,[1]对照表!$AA$3:$AA$13),LOOKUP($N13,[1]对照表!$Z$15:$Z$25,[1]对照表!$AA$15:$AA$25)) -> 0 | P13: =M13+O13 -> 68 | Q13: 3.25 | R13: =IF(B13="高三",IF($E13="男",LOOKUP(Q13,[1]对照表!$W$3:$W$24,[1]对照表!$X$3:$X$24),LOOKUP(Q13,[1]对照表!$W$27:$W$48,[1]对照表!$X$27:$X$48)),IF(B13="高二",IF($E13="男",LOOKUP(Q13,[1]对照表!$V$3:$V$24,[1]对照表!$X$3:$X$24),LOOKUP(Q13,[1]对照表!$V$27:$V$48,[1]对照表!$X$27:$X$48)),IF(B13="高一",IF($E13="男",LOOKUP(Q13,[1]对照表!$U$3:$U$24,[1]对照表!$X$3:$X$24),LOOKUP(Q13,[1]对照表!$U$27:$U$48,[1]对照表!$X$27:$X$48))))) -> 100 | S13: =ROUND(IF(IF($B13="高三",MIN(IF($E13="男",$Q13-3.2,$Q13-3.2),0),IF($B13="高二",MIN(IF($E13="男",$Q13-3.25,$Q13-3.22),0),IF($B13="高一",MIN(IF($E13="男",$Q13-3.3,$Q13-3.24),0))))<-0.6,IF($B13="高三",MIN(IF($E13="男",$Q13-3.2,$Q13-3.2),0),IF($B13="高二",MIN(IF($E13="男",$Q13-3.25,$Q13-3.22),0),IF($B13="高一",MIN(IF($E13="男",$Q13-3.3,$Q13-3.24),0))))+0.4,IF($B13="高三",MIN(IF($E13="男",$Q13-3.2,$Q13-3.2),0),IF($B13="高二",MIN(IF($E13="男",$Q13-3.25,$Q13-3.22),0),IF($B13="高一",MIN(IF($E13="男",$Q13-3.3,$Q13-3.24),0))))),2) -> -0.05 | T13: =IF(E13="男",LOOKUP($S13,[1]对照表!$AB$3:$AB$13,[1]对照表!$AC$3:$AC$13),LOOKUP($S13,[1]对照表!$AB$15:$AB$25,[1]对照表!$AC$15:$AC$25)) -> 1 | U13: =R13+T13 -> 101 | V13: =SUM(I13,K13,M13)/3*0.3+SUM(G13,R13)/2*0.4 -> 60.8 | W13: =O13+T13 -> 1 | X13: =V13/0.7+W13 -> 87.857143 | Y13: 87.857143
... A25: 11 | B25: 高一 | C25: 101 | D25: 何宇铮 | E25: 男 | F25: 7.8 | G25: =IF(B25="高三",IF($E25="男",LOOKUP(F25,[1]对照表!$G$3:$G$24,[1]对照表!$H$3:$H$24),LOOKUP(F25,[1]对照表!$G$27:$G$48,[1]对照表!$H$27:$H$48)),IF(B25="高二",IF($E25="男",LOOKUP(F25,[1]对照表!$F$3:$F$24,[1]对照表!$H$3:$H$24),LOOKUP(F25,[1]对照表!$F$27:$F$48,[1]对照表!$H$27:$H$48)),IF(B25="高一",IF($E25="男",LOOKUP(F25,[1]对照表!$E$3:$E$24,[1]对照表!$H$3:$H$24),LOOKUP(F25,[1]对照表!$E$27:$E$48,[1]对照表!$H$27:$H$48))))) -> 76 | H25: 17.7 | I25: =IF(B25="高三",IF($E25="男",LOOKUP(H25,[1]对照表!$K$3:$K$24,[1]对照表!$L$3:$L$24),LOOKUP(H25,[1]对照表!$K$27:$K$48,[1]对照表!$L$27:$L$48)),IF(B25="高二",IF($E25="男",LOOKUP(H25,[1]对照表!$J$3:$J$24,[1]对照表!$L$3:$L$24),LOOKUP(H25,[1]对照表!$J$27:$J$48,[1]对照表!$L$27:$L$48)),IF(B25="高一",IF($E25="男",LOOKUP(H25,[1]对照表!$I$3:$I$24,[1]对照表!$L$3:$L$24),LOOKUP(H25,[1]对照表!$I$27:$I$48,[1]对照表!$L$27:$L$48))))) -> 85 | J25: 225 | K25: =IF(B25="高三",IF($E25="男",LOOKUP(J25,[1]对照表!$O$3:$O$24,[1]对照表!$P$3:$P$24),LOOKUP(J25,[1]对照表!$O$27:$O$48,[1]对照表!$P$27:$P$48)),IF(B25="高二",IF($E25="男",LOOKUP(J25,[1]对照表!$N$3:$N$24,[1]对照表!$P$3:$P$24),LOOKUP(J25,[1]对照表!$N$27:$N$48,[1]对照表!$P$27:$P$48)),IF(B25="高一",IF($E25="男",LOOKUP(J25,[1]对照表!$M$3:$M$24,[1]对照表!$P$3:$P$24),LOOKUP(J25,[1]对照表!$M$27:$M$48,[1]对照表!$P$27:$P$48))))) -> 74 | L25: 15 | M25: =IF(B25="高三",IF($E25="男",LOOKUP(L25,[1]对照表!$S$3:$S$24,[1]对照表!$T$3:$T$24),LOOKUP(L25,[1]对照表!$S$27:$S$48,[1]对照表!$T$27:$T$48)),IF(B25="高二",IF($E25="男",LOOKUP(L25,[1]对照表!$R$3:$R$24,[1]对照表!$T$3:$T$24),LOOKUP(L25,[1]对照表!$R$27:$R$48,[1]对照表!$T$27:$T$48)),IF(B25="高一",IF($E25="男",LOOKUP(L25,[1]对照表!$Q$3:$Q$24,[1]对照表!$T$3:$T$24),LOOKUP(L25,[1]对照表!$Q$27:$Q$48,[1]对照表!$T$27:$T$48))))) -> 95 | N25: =IF(B25="高三",MAX(IF(E25="男",L25-18,L25-55),0),IF(B25="高二",MAX(IF(E25="男",L25-17,L25-54),0),IF(B25="高一",MAX(IF(E25="男",L25-16,L25-53),0)))) -> 0 | O25: =IF(E25="男",LOOKUP($N25,[1]对照表!$Z$3:$Z$13,[1]对照表!$AA$3:$AA$13),LOOKUP($N25,[1]对照表!$Z$15:$Z$25,[1]对照表!$AA$15:$AA$25)) -> 0 | P25: =M25+O25 -> 95 | Q25: 4.12 | R25: =IF(B25="高三",IF($E25="男",LOOKUP(Q25,[1]对照表!$W$3:$W$24,[1]对照表!$X$3:$X$24),LOOKUP(Q25,[1]对照表!$W$27:$W$48,[1]对照表!$X$27:$X$48)),IF(B25="高二",IF($E25="男",LOOKUP(Q25,[1]对照表!$V$3:$V$24,[1]对照表!$X$3:$X$24),LOOKUP(Q25,[1]对照表!$V$27:$V$48,[1]对照表!$X$27:$X$48)),IF(B25="高一",IF($E25="男",LOOKUP(Q25,[1]对照表!$U$3:$U$24,[1]对照表!$X$3:$X$24),LOOKUP(Q25,[1]对照表!$U$27:$U$48,[1]对照表!$X$27:$X$48))))) -> 72 | S25: =ROUND(IF(IF($B25="高三",MIN(IF($E25="男",$Q25-3.2,$Q25-3.2),0),IF($B25="高二",MIN(IF($E25="男",$Q25-3.25,$Q25-3.22),0),IF($B25="高一",MIN(IF($E25="男",$Q25-3.3,$Q25-3.24),0))))<-0.6,IF($B25="高三",MIN(IF($E25="男",$Q25-3.2,$Q25-3.2),0),IF($B25="高二",MIN(IF($E25="男",$Q25-3.25,$Q25-3.22),0),IF($B25="高一",MIN(IF($E25="男",$Q25-3.3,$Q25-3.24),0))))+0.4,IF($B25="高三",MIN(IF($E25="男",$Q25-3.2,$Q25-3.2),0),IF($B25="高二",MIN(IF($E25="男",$Q25-3.25,$Q25-3.22),0),IF($B25="高一",MIN(IF($E25="男",$Q25-3.3,$Q25-3.24),0))))),2) -> 0 | T25: =IF(E25="男",LOOKUP($S25,[1]对照表!$AB$3:$AB$13,[1]对照表!$AC$3:$AC$13),LOOKUP($S25,[1]对照表!$AB$15:$AB$25,[1]对照表!$AC$15:$AC$25)) -> 0 | U25: =R25+T25 -> 72 | V25: =SUM(I25,K25,M25)/3*0.3+SUM(G25,R25)/2*0.4 -> 55 | W25: =O25+T25 -> 0 | X25: =V25/0.7+W25 -> 78.571429 | Y25: 78.571429
A26: 3 | B26: 高一 | C26: 101 | D26: 陈桓毅 | E26: 男 | F26: 6.7 | G26: =IF(B26="高三",IF($E26="男",LOOKUP(F26,[1]对照表!$G$3:$G$24,[1]对照表!$H$3:$H$24),LOOKUP(F26,[1]对照表!$G$27:$G$48,[1]对照表!$H$27:$H$48)),IF(B26="高二",IF($E26="男",LOOKUP(F26,[1]对照表!$F$3:$F$24,[1]对照表!$H$3:$H$24),LOOKUP(F26,[1]对照表!$F$27:$F$48,[1]对照表!$H$27:$H$48)),IF(B26="高一",IF($E26="男",LOOKUP(F26,[1]对照表!$E$3:$E$24,[1]对照表!$H$3:$H$24),LOOKUP(F26,[1]对照表!$E$27:$E$48,[1]对照表!$H$27:$H$48))))) -> 100 | H26: 6.1 | I26: =IF(B26="高三",IF($E26="男",LOOKUP(H26,[1]对照表!$K$3:$K$24,[1]对照表!$L$3:$L$24),LOOKUP(H26,[1]对照表!$K$27:$K$48,[1]对照表!$L$27:$L$48)),IF(B26="高二",IF($E26="男",LOOKUP(H26,[1]对照表!$J$3:$J$24,[1]对照表!$L$3:$L$24),LOOKUP(H26,[1]对照表!$J$27:$J$48,[1]对照表!$L$27:$L$48)),IF(B26="高一",IF($E26="男",LOOKUP(H26,[1]对照表!$I$3:$I$24,[1]对照表!$L$3:$L$24),LOOKUP(H26,[1]对照表!$I$27:$I$48,[1]对照表!$L$27:$L$48))))) -> 66 | J26: 228 | K26: =IF(B26="高三",IF($E26="男",LOOKUP(J26,[1]对照表!$O$3:$O$24,[1]对照表!$P$3:$P$24),LOOKUP(J26,[1]对照表!$O$27:$O$48,[1]对照表!$P$27:$P$48)),IF(B26="高二",IF($E26="男",LOOKUP(J26,[1]对照表!$N$3:$N$24,[1]对照表!$P$3:$P$24),LOOKUP(J26,[1]对照表!$N$27:$N$48,[1]对照表!$P$27:$P$48)),IF(B26="高一",IF($E26="男",LOOKUP(J26,[1]对照表!$M$3:$M$24,[1]对照表!$P$3:$P$24),LOOKUP(J26,[1]对照表!$M$27:$M$48,[1]对照表!$P$27:$P$48))))) -> 76 | L26: 假 | M26: 0 | N26: 0 | O26: =IF(E26="男",LOOKUP($N26,[1]对照表!$Z$3:$Z$13,[1]对照表!$AA$3:$AA$13),LOOKUP($N26,[1]对照表!$Z$15:$Z$25,[1]对照表!$AA$15:$AA$25)) -> 0 | P26: =M26+O26 -> 0 | Q26: 3.23 | R26: =IF(B26="高三",IF($E26="男",LOOKUP(Q26,[1]对照表!$W$3:$W$24,[1]对照表!$X$3:$X$24),LOOKUP(Q26,[1]对照表!$W$27:$W$48,[1]对照表!$X$27:$X$48)),IF(B26="高二",IF($E26="男",LOOKUP(Q26,[1]对照表!$V$3:$V$24,[1]对照表!$X$3:$X$24),LOOKUP(Q26,[1]对照表!$V$27:$V$48,[1]对照表!$X$27:$X$48)),IF(B26="高一",IF($E26="男",LOOKUP(Q26,[1]对照表!$U$3:$U$24,[1]对照表!$X$3:$X$24),LOOKUP(Q26,[1]对照表!$U$27:$U$48,[1]对照表!$X$27:$X$48))))) -> 100 | S26: =ROUND(IF(IF($B26="高三",MIN(IF($E26="男",$Q26-3.2,$Q26-3.2),0),IF($B26="高二",MIN(IF($E26="男",$Q26-3.25,$Q26-3.22),0),IF($B26="高一",MIN(IF($E26="男",$Q26-3.3,$Q26-3.24),0))))<-0.6,IF($B26="高三",MIN(IF($E26="男",$Q26-3.2,$Q26-3.2),0),IF($B26="高二",MIN(IF($E26="男",$Q26-3.25,$Q26-3.22),0),IF($B26="高一",MIN(IF($E26="男",$Q26-3.3,$Q26-3.24),0))))+0.4,IF($B26="高三",MIN(IF($E26="男",$Q26-3.2,$Q26-3.2),0),IF($B26="高二",MIN(IF($E26="男",$Q26-3.25,$Q26-3.22),0),IF($B26="高一",MIN(IF($E26="男",$Q26-3.3,$Q26-3.24),0))))),2) -> -0.07 | T26: =IF(E26="男",LOOKUP($S26,[1]对照表!$AB$3:$AB$13,[1]对照表!$AC$3:$AC$13),LOOKUP($S26,[1]对照表!$AB$15:$AB$25,[1]对照表!$AC$15:$AC$25)) -> 1 | U26: =R26+T26 -> 101 | V26: =SUM(I26,K26,M26)/3*0.3+SUM(G26,R26)/2*0.4 -> 54.2 | W26: =O26+T26 -> 1 | X26: =V26/0.7+W26 -> 78.428571 | Y26: 78.428571
A27: 47 | B27: 高一 | C27: 101 | D27: 姚馨怡 | E27: 女 | F27: 8.54 | G27: =IF(B27="高三",IF($E27="男",LOOKUP(F27,[1]对照表!$G$3:$G$24,[1]对照表!$H$3:$H$24),LOOKUP(F27,[1]对照表!$G$27:$G$48,[1]对照表!$H$27:$H$48)),IF(B27="高二",IF($E27="男",LOOKUP(F27,[1]对照表!$F$3:$F$24,[1]对照表!$H$3:$H$24),LOOKUP(F27,[1]对照表!$F$27:$F$48,[1]对照表!$H$27:$H$48)),IF(B27="高一",IF($E27="男",LOOKUP(F27,[1]对照表!$E$3:$E$24,[1]对照表!$H$3:$H$24),LOOKUP(F27,[1]对照表!$E$27:$E$48,[1]对照表!$H$27:$H$48))))) -> 80 | H27: 20.5 | I27: =IF(B27="高三",IF($E27="男",LOOKUP(H27,[1]对照表!$K$3:$K$24,[1]对照表!$L$3:$L$24),LOOKUP(H27,[1]对照表!$K$27:$K$48,[1]对照表!$L$27:$L$48)),IF(B27="高二",IF($E27="男",LOOKUP(H27,[1]对照表!$J$3:$J$24,[1]对照表!$L$3:$L$24),LOOKUP(H27,[1]对照表!$J$27:$J$48,[1]对照表!$L$27:$L$48)),IF(B27="高一",IF($E27="男",LOOKUP(H27,[1]对照表!$I$3:$I$24,[1]对照表!$L$3:$L$24),LOOKUP(H27,[1]对照表!$I$27:$I$48,[1]对照表!$L$27:$L$48))))) -> 85 | J27: 190 | K27: =IF(B27="高三",IF($E27="男",LOOKUP(J27,[1]对照表!$O$3:$O$24,[1]对照表!$P$3:$P$24),LOOKUP(J27,[1]对照表!$O$27:$O$48,[1]对照表!$P$27:$P$48)),IF(B27="高二",IF($E27="男",LOOKUP(J27,[1]对照表!$N$3:$N$24,[1]对照表!$P$3:$P$24),LOOKUP(J27,[1]对照表!$N$27:$N$48,[1]对照表!$P$27:$P$48)),IF(B27="高一",IF($E27="男",LOOKUP(J27,[1]对照表!$M$3:$M$24,[1]对照表!$P$3:$P$24),LOOKUP(J27,[1]对照表!$M$27:$M$48,[1]对照表!$P$27:$P$48))))) -> 85 | L27: 63 | M27: =IF(B27="高三",IF($E27="男",LOOKUP(L27,[1]对照表!$S$3:$S$24,[1]对照表!$T$3:$T$24),LOOKUP(L27,[1]对照表!$S$27:$S$48,[1]对照表!$T$27:$T$48)),IF(B27="高二",IF($E27="男",LOOKUP(L27,[1]对照表!$R$3:$R$24,[1]对照表!$T$3:$T$24),LOOKUP(L27,[1]对照表!$R$27:$R$48,[1]对照表!$T$27:$T$48)),IF(B27="高一",IF($E27="男",LOOKUP(L27,[1]对照表!$Q$3:$Q$24,[1]对照表!$T$3:$T$24),LOOKUP(L27,[1]对照表!$Q$27:$Q$48,[1]对照表!$T$27:$T$48))))) -> 100 | N27: =IF(B27="高三",MAX(IF(E27="男",L27-18,L27-55),0),IF(B27="高二",MAX(IF(E27="男",L27-17,L27-54),0),IF(B27="高一",MAX(IF(E27="男",L27-16,L27-53),0)))) -> 10 | O27: =IF(E27="男",LOOKUP($N27,[1]对照表!$Z$3:$Z$13,[1]对照表!$AA$3:$AA$13),LOOKUP($N27,[1]对照表!$Z$15:$Z$25,[1]对照表!$AA$15:$AA$25)) -> 7 | P27: =M27+O27 -> 107 | Q27: 3.39 | R27: =IF(B27="高三",IF($E27="男",LOOKUP(Q27,[1]对照表!$W$3:$W$24,[1]对照表!$X$3:$X$24),LOOKUP(Q27,[1]对照表!$W$27:$W$48,[1]对照表!$X$27:$X$48)),IF(B27="高二",IF($E27="男",LOOKUP(Q27,[1]对照表!$V$3:$V$24,[1]对照表!$X$3:$X$24),LOOKUP(Q27,[1]对照表!$V$27:$V$48,[1]对照表!$X$27:$X$48)),IF(B27="高一",IF($E27="男",LOOKUP(Q27,[1]对照表!$U$3:$U$24,[1]对照表!$X$3:$X$24),LOOKUP(Q27,[1]对照表!$U$27:$U$48,[1]对照表!$X$27:$X$48))))) -> 85 | S27: =ROUND(IF(IF($B27="高三",MIN(IF($E27="男",$Q27-3.2,$Q27-3.2),0),IF($B27="高二",MIN(IF($E27="男",$Q27-3.25,$Q27-3.22),0),IF($B27="高一",MIN(IF($E27="男",$Q27-3.3,$Q27-3.24),0))))<-0.6,IF($B27="高三",MIN(IF($E27="男",$Q27-3.2,$Q27-3.2),0),IF($B27="高二",MIN(IF($E27="男",$Q27-3.25,$Q27-3.22),0),IF($B27="高一",MIN(IF($E27="男",$Q27-3.3,$Q27-3.24),0))))+0.4,IF($B27="高三",MIN(IF($E27="男",$Q27-3.2,$Q27-3.2),0),IF($B27="高二",MIN(IF($E27="男",$Q27-3.25,$Q27-3.22),0),IF($B27="高一",MIN(IF($E27="男",$Q27-3.3,$Q27-3.24),0))))),2) -> 0 | T27: =IF(E27="男",LOOKUP($S27,[1]对照表!$AB$3:$AB$13,[1]对照表!$AC$3:$AC$13),LOOKUP($S27,[1]对照表!$AB$15:$AB$25,[1]对照表!$AC$15:$AC$25)) -> 0 | U27: =R27+T27 -> 85 | V27: =SUM(I27,K27,M27)/3*0.3+SUM(G27,R27)/2*0.4 -> 60 | W27: =O27+T27 -> 7 | X27: =V27/0.7+W27 -> 92.714286 | Y27: 92.714286
A28: 6 | B28: 高一 | C28: 101 | D28: 丁奕天 | E28: 男 | F28: 8.5 | G28: =IF(B28="高三",IF($E28="男",LOOKUP(F28,[1]对照表!$G$3:$G$24,[1]对照表!$H$3:$H$24),LOOKUP(F28,[1]对照表!$G$27:$G$48,[1]对照表!$H$27:$H$48)),IF(B28="高二",IF($E28="男",LOOKUP(F28,[1]对照表!$F$3:$F$24,[1]对照表!$H$3:$H$24),LOOKUP(F28,[1]对照表!$F$27:$F$48,[1]对照表!$H$27:$H$48)),IF(B28="高一",IF($E28="男",LOOKUP(F28,[1]对照表!$E$3:$E$24,[1]对照表!$H$3:$H$24),LOOKUP(F28,[1]对照表!$E$27:$E$48,[1]对照表!$H$27:$H$48))))) -> 70 | H28: 16.5 | I28: =IF(B28="高三",IF($E28="男",LOOKUP(H28,[1]对照表!$K$3:$K$24,[1]对照表!$L$3:$L$24),LOOKUP(H28,[1]对照表!$K$27:$K$48,[1]对照表!$L$27:$L$48)),IF(B28="高二",IF($E28="男",LOOKUP(H28,[1]对照表!$J$3:$J$24,[1]对照表!$L$3:$L$24),LOOKUP(H28,[1]对照表!$J$27:$J$48,[1]对照表!$L$27:$L$48)),IF(B28="高一",IF($E28="男",LOOKUP(H28,[1]对照表!$I$3:$I$24,[1]对照表!$L$3:$L$24),LOOKUP(H28,[1]对照表!$I$27:$I$48,[1]对照表!$L$27:$L$48))))) -> 80 | J28: 214 | K28: =IF(B28="高三",IF($E28="男",LOOKUP(J28,[1]对照表!$O$3:$O$24,[1]对照表!$P$3:$P$24),LOOKUP(J28,[1]对照表!$O$27:$O$48,[1]对照表!$P$27:$P$48)),IF(B28="高二",IF($E28="男",LOOKUP(J28,[1]对照表!$N$3:$N$24,[1]对照表!$P$3:$P$24),LOOKUP(J28,[1]对照表!$N$27:$N$48,[1]对照表!$P$27:$P$48)),IF(B28="高一",IF($E28="男",LOOKUP(J28,[1]对照表!$M$3:$M$24,[1]对照表!$P$3:$P$24),LOOKUP(J28,[1]对照表!$M$27:$M$48,[1]对照表!$P$27:$P$48))))) -> 68 | L28: 10 | M28: =IF(B28="高三",IF($E28="男",LOOKUP(L28,[1]对照表!$S$3:$S$24,[1]对照表!$T$3:$T$24),LOOKUP(L28,[1]对照表!$S$27:$S$48,[1]对照表!$T$27:$T$48)),IF(B28="高二",IF($E28="男",LOOKUP(L28,[1]对照表!$R$3:$R$24,[1]对照表!$T$3:$T$24),LOOKUP(L28,[1]对照表!$R$27:$R$48,[1]对照表!$T$27:$T$48)),IF(B28="高一",IF($E28="男",LOOKUP(L28,[1]对照表!$Q$3:$Q$24,[1]对照表!$T$3:$T$24),LOOKUP(L28,[1]对照表!$Q$27:$Q$48,[1]对照表!$T$27:$T$48))))) -> 72 | N28: =IF(B28="高三",MAX(IF(E28="男",L28-18,L28-55),0),IF(B28="高二",MAX(IF(E28="男",L28-17,L28-54),0),IF(B28="高一",MAX(IF(E28="男",L28-16,L28-53),0)))) -> 0 | O28: =IF(E28="男",LOOKUP($N28,[1]对照表!$Z$3:$Z$13,[1]对照表!$AA$3:$AA$13),LOOKUP($N28,[1]对照表!$Z$15:$Z$25,[1]对照表!$AA$15:$AA$25)) -> 0 | P28: =M28+O28 -> 72 | Q28: 4.02 | R28: =IF(B28="高三",IF($E28="男",LOOKUP(Q28,[1]对照表!$W$3:$W$24,[1]对照表!$X$3:$X$24),LOOKUP(Q28,[1]对照表!$W$27:$W$48,[1]对照表!$X$27:$X$48)),IF(B28="高二",IF($E28="男",LOOKUP(Q28,[1]对照表!$V$3:$V$24,[1]对照表!$X$3:$X$24),LOOKUP(Q28,[1]对照表!$V$27:$V$48,[1]对照表!$X$27:$X$48)),IF(B28="高一",IF($E28="男",LOOKUP(Q28,[1]对照表!$U$3:$U$24,[1]对照表!$X$3:$X$24),LOOKUP(Q28,[1]对照表!$U$27:$U$48,[1]对照表!$X$27:$X$48))))) -> 76 | S28: =ROUND(IF(IF($B28="高三",MIN(IF($E28="男",$Q28-3.2,$Q28-3.2),0),IF($B28="高二",MIN(IF($E28="男",$Q28-3.25,$Q28-3.22),0),IF($B28="高一",MIN(IF($E28="男",$Q28-3.3,$Q28-3.24),0))))<-0.6,IF($B28="高三",MIN(IF($E28="男",$Q28-3.2,$Q28-3.2),0),IF($B28="高二",MIN(IF($E28="男",$Q28-3.25,$Q28-3.22),0),IF($B28="高一",MIN(IF($E28="男",$Q28-3.3,$Q28-3.24),0))))+0.4,IF($B28="高三",MIN(IF($E28="男",$Q28-3.2,$Q28-3.2),0),IF($B28="高二",MIN(IF($E28="男",$Q28-3.25,$Q28-3.22),0),IF($B28="高一",MIN(IF($E28="男",$Q28-3.3,$Q28-3.24),0))))),2) -> 0 | T28: =IF(E28="男",LOOKUP($S28,[1]对照表!$AB$3:$AB$13,[1]对照表!$AC$3:$AC$13),LOOKUP($S28,[1]对照表!$AB$15:$AB$25,[1]对照表!$AC$15:$AC$25)) -> 0 | U28: =R28+T28 -> 76 | V28: =SUM(I28,K28,M28)/3*0.3+SUM(G28,R28)/2*0.4 -> 51.2 | W28: =O28+T28 -> 0 | X28: =V28/0.7+W28 -> 73.142857 | Y28: 73.142857
A29: 24 | B29: 高一 | C29: 101 | D29: 马晗迪 | E29: 男 | F29: 7.5 | G29: =IF(B29="高三",IF($E29="男",LOOKUP(F29,[1]对照表!$G$3:$G$24,[1]对照表!$H$3:$H$24),LOOKUP(F29,[1]对照表!$G$27:$G$48,[1]对照表!$H$27:$H$48)),IF(B29="高二",IF($E29="男",LOOKUP(F29,[1]对照表!$F$3:$F$24,[1]对照表!$H$3:$H$24),LOOKUP(F29,[1]对照表!$F$27:$F$48,[1]对照表!$H$27:$H$48)),IF(B29="高一",IF($E29="男",LOOKUP(F29,[1]对照表!$E$3:$E$24,[1]对照表!$H$3:$H$24),LOOKUP(F29,[1]对照表!$E$27:$E$48,[1]对照表!$H$27:$H$48))))) -> 80 | H29: 7.5 | I29: =IF(B29="高三",IF($E29="男",LOOKUP(H29,[1]对照表!$K$3:$K$24,[1]对照表!$L$3:$L$24),LOOKUP(H29,[1]对照表!$K$27:$K$48,[1]对照表!$L$27:$L$48)),IF(B29="高二",IF($E29="男",LOOKUP(H29,[1]对照表!$J$3:$J$24,[1]对照表!$L$3:$L$24),LOOKUP(H29,[1]对照表!$J$27:$J$48,[1]对照表!$L$27:$L$48)),IF(B29="高一",IF($E29="男",LOOKUP(H29,[1]对照表!$I$3:$I$24,[1]对照表!$L$3:$L$24),LOOKUP(H29,[1]对照表!$I$27:$I$48,[1]对照表!$L$27:$L$48))))) -> 68 | J29: 202 | K29: =IF(B29="高三",IF($E29="男",LOOKUP(J29,[1]对照表!$O$3:$O$24,[1]对照表!$P$3:$P$24),LOOKUP(J29,[1]对照表!$O$27:$O$48,[1]对照表!$P$27:$P$48)),IF(B29="高二",IF($E29="男",LOOKUP(J29,[1]对照表!$N$3:$N$24,[1]对照表!$P$3:$P$24),LOOKUP(J29,[1]对照表!$N$27:$N$48,[1]对照表!$P$27:$P$48)),IF(B29="高一",IF($E29="男",LOOKUP(J29,[1]对照表!$M$3:$M$24,[1]对照表!$P$3:$P$24),LOOKUP(J29,[1]对照表!$M$27:$M$48,[1]对照表!$P$27:$P$48))))) -> 62 | L29: 8 | M29: =IF(B29="高三",IF($E29="男",LOOKUP(L29,[1]对照表!$S$3:$S$24,[1]对照表!$T$3:$T$24),LOOKUP(L29,[1]对照表!$S$27:$S$48,[1]对照表!$T$27:$T$48)),IF(B29="高二",IF($E29="男",LOOKUP(L29,[1]对照表!$R$3:$R$24,[1]对照表!$T$3:$T$24),LOOKUP(L29,[1]对照表!$R$27:$R$48,[1]对照表!$T$27:$T$48)),IF(B29="高一",IF($E29="男",LOOKUP(L29,[1]对照表!$Q$3:$Q$24,[1]对照表!$T$3:$T$24),LOOKUP(L29,[1]对照表!$Q$27:$Q$48,[1]对照表!$T$27:$T$48))))) -> 64 | N29: =IF(B29="高三",MAX(IF(E29="男",L29-18,L29-55),0),IF(B29="高二",MAX(IF(E29="男",L29-17,L29-54),0),IF(B29="高一",MAX(IF(E29="男",L29-16,L29-53),0)))) -> 0 | O29: =IF(E29="男",LOOKUP($N29,[1]对照表!$Z$3:$Z$13,[1]对照表!$AA$3:$AA$13),LOOKUP($N29,[1]对照表!$Z$15:$Z$25,[1]对照表!$AA$15:$AA$25)) -> 0 | P29: =M29+O29 -> 64 | Q29: 3.59 | R29: =IF(B29="高三",IF($E29="男",LOOKUP(Q29,[1]对照表!$W$3:$W$24,[1]对照表!$X$3:$X$24),LOOKUP(Q29,[1]对照表!$W$27:$W$48,[1]对照表!$X$27:$X$48)),IF(B29="高二",IF($E29="男",LOOKUP(Q29,[1]对照表!$V$3:$V$24,[1]对照表!$X$3:$X$24),LOOKUP(Q29,[1]对照表!$V$27:$V$48,[1]对照表!$X$27:$X$48)),IF(B29="高一",IF($E29="男",LOOKUP(Q29,[1]对照表!$U$3:$U$24,[1]对照表!$X$3:$X$24),LOOKUP(Q29,[1]对照表!$U$27:$U$48,[1]对照表!$X$27:$X$48))))) -> 78 | S29: =ROUND(IF(IF($B29="高三",MIN(IF($E29="男",$Q29-3.2,$Q29-3.2),0),IF($B29="高二",MIN(IF($E29="男",$Q29-3.25,$Q29-3.22),0),IF($B29="高一",MIN(IF($E29="男",$Q29-3.3,$Q29-3.24),0))))<-0.6,IF($B29="高三",MIN(IF($E29="男",$Q29-3.2,$Q29-3.2),0),IF($B29="高二",MIN(IF($E29="男",$Q29-3.25,$Q29-3.22),0),IF($B29="高一",MIN(IF($E29="男",$Q29-3.3,$Q29-3.24),0))))+0.4,IF($B29="高三",MIN(IF($E29="男",$Q29-3.2,$Q29-3.2),0),IF($B29="高二",MIN(IF($E29="男",$Q29-3.25,$Q29-3.22),0),IF($B29="高一",MIN(IF($E29="男",$Q29-3.3,$Q29-3.24),0))))),2) -> 0 | T29: =IF(E29="男",LOOKUP($S29,[1]对照表!$AB$3:$AB$13,[1]对照表!$AC$3:$AC$13),LOOKUP($S29,[1]对照表!$AB$15:$AB$25,[1]对照表!$AC$15:$AC$25)) -> 0 | U29: =R29+T29 -> 78 | V29: =SUM(I29,K29,M29)/3*0.3+SUM(G29,R29)/2*0.4 -> 51 | W29: =O29+T29 -> 0 | X29: =V29/0.7+W29 -> 72.857143 | Y29: 72.857143
A30: 12 | B30: 高一 | C30: 101 | D30: 胡清源 | E30: 男 | F30: 8.3 | G30: =IF(B30="高三",IF($E30="男",LOOKUP(F30,[1]对照表!$G$3:$G$24,[1]对照表!$H$3:$H$24),LOOKUP(F30,[1]对照表!$G$27:$G$48,[1]对照表!$H$27:$H$48)),IF(B30="高二",IF($E30="男",LOOKUP(F30,[1]对照表!$F$3:$F$24,[1]对照表!$H$3:$H$24),LOOKUP(F30,[1]对照表!$F$27:$F$48,[1]对照表!$H$27:$H$48)),IF(B30="高一",IF($E30="男",LOOKUP(F30,[1]对照表!$E$3:$E$24,[1]对照表!$H$3:$H$24),LOOKUP(F30,[1]对照表!$E$27:$E$48,[1]对照表!$H$27:$H$48))))) -> 72 | H30: 12 | I30: =IF(B30="高三",IF($E30="男",LOOKUP(H30,[1]对照表!$K$3:$K$24,[1]对照表!$L$3:$L$24),LOOKUP(H30,[1]对照表!$K$27:$K$48,[1]对照表!$L$27:$L$48)),IF(B30="高二",IF($E30="男",LOOKUP(H30,[1]对照表!$J$3:$J$24,[1]对照表!$L$3:$L$24),LOOKUP(H30,[1]对照表!$J$27:$J$48,[1]对照表!$L$27:$L$48)),IF(B30="高一",IF($E30="男",LOOKUP(H30,[1]对照表!$I$3:$I$24,[1]对照表!$L$3:$L$24),LOOKUP(H30,[1]对照表!$I$27:$I$48,[1]对照表!$L$27:$L$48))))) -> 74 | J30: 209 | K30: =IF(B30="高三",IF($E30="男",LOOKUP(J30,[1]对照表!$O$3:$O$24,[1]对照表!$P$3:$P$24),LOOKUP(J30,[1]对照表!$O$27:$O$48,[1]对照表!$P$27:$P$48)),IF(B30="高二",IF($E30="男",LOOKUP(J30,[1]对照表!$N$3:$N$24,[1]对照表!$P$3:$P$24),LOOKUP(J30,[1]对照表!$N$27:$N$48,[1]对照表!$P$27:$P$48)),IF(B30="高一",IF($E30="男",LOOKUP(J30,[1]对照表!$M$3:$M$24,[1]对照表!$P$3:$P$24),LOOKUP(J30,[1]对照表!$M$27:$M$48,[1]对照表!$P$27:$P$48))))) -> 66 | L30: 8 | M30: =IF(B30="高三",IF($E30="男",LOOKUP(L30,[1]对照表!$S$3:$S$24,[1]对照表!$T$3:$T$24),LOOKUP(L30,[1]对照表!$S$27:$S$48,[1]对照表!$T$27:$T$48)),IF(B30="高二",IF($E30="男",LOOKUP(L30,[1]对照表!$R$3:$R$24,[1]对照表!$T$3:$T$24),LOOKUP(L30,[1]对照表!$R$27:$R$48,[1]对照表!$T$27:$T$48)),IF(B30="高一",IF($E30="男",LOOKUP(L30,[1]对照表!$Q$3:$Q$24,[1]对照表!$T$3:$T$24),LOOKUP(L30,[1]对照表!$Q$27:$Q$48,[1]对照表!$T$27:$T$48))))) -> 64 | N30: =IF(B30="高三",MAX(IF(E30="男",L30-18,L30-55),0),IF(B30="高二",MAX(IF(E30="男",L30-17,L30-54),0),IF(B30="高一",MAX(IF(E30="男",L30-16,L30-53),0)))) -> 0 | O30: =IF(E30="男",LOOKUP($N30,[1]对照表!$Z$3:$Z$13,[1]对照表!$AA$3:$AA$13),LOOKUP($N30,[1]对照表!$Z$15:$Z$25,[1]对照表!$AA$15:$AA$25)) -> 0 | P30: =M30+O30 -> 64 | Q30: 3.49 | R30: =IF(B30="高三",IF($E30="男",LOOKUP(Q30,[1]对照表!$W$3:$W$24,[1]对照表!$X$3:$X$24),LOOKUP(Q30,[1]对照表!$W$27:$W$48,[1]对照表!$X$27:$X$48)),IF(B30="高二",IF($E30="男",LOOKUP(Q30,[1]对照表!$V$3:$V$24,[1]对照表!$X$3:$X$24),LOOKUP(Q30,[1]对照表!$V$27:$V$48,[1]对照表!$X$27:$X$48)),IF(B30="高一",IF($E30="男",LOOKUP(Q30,[1]对照表!$U$3:$U$24,[1]对照表!$X$3:$X$24),LOOKUP(Q30,[1]对照表!$U$27:$U$48,[1]对照表!$X$27:$X$48))))) -> 80 | S30: =ROUND(IF(IF($B30="高三",MIN(IF($E30="男",$Q30-3.2,$Q30-3.2),0),IF($B30="高二",MIN(IF($E30="男",$Q30-3.25,$Q30-3.22),0),IF($B30="高一",MIN(IF($E30="男",$Q30-3.3,$Q30-3.24),0))))<-0.6,IF($B30="高三",MIN(IF($E30="男",$Q30-3.2,$Q30-3.2),0),IF($B30="高二",MIN(IF($E30="男",$Q30-3.25,$Q30-3.22),0),IF($B30="高一",MIN(IF($E30="男",$Q30-3.3,$Q30-3.24),0))))+0.4,IF($B30="高三",MIN(IF($E30="男",$Q30-3.2,$Q30-3.2),0),IF($B30="高二",MIN(IF($E30="男",$Q30-3.25,$Q30-3.22),0),IF($B30="高一",MIN(IF($E30="男",$Q30-3.3,$Q30-3.24),0))))),2) -> 0 | T30: =IF(E30="男",LOOKUP($S30,[1]对照表!$AB$3:$AB$13,[1]对照表!$AC$3:$AC$13),LOOKUP($S30,[1]对照表!$AB$15:$AB$25,[1]对照表!$AC$15:$AC$25)) -> 0 | U30: =R30+T30 -> 80 | V30: =SUM(I30,K30,M30)/3*0.3+SUM(G30,R30)/2*0.4 -> 50.8 | W30: =O30+T30 -> 0 | X30: =V30/0.7+W30 -> 72.571429 | Y30: 72.571429
A31: 17 | B31: 高一 | C31: 101 | D31: 李奕诚 | E31: 男 | F31: 8.1 | G31: =IF(B31="高三",IF($E31="男",LOOKUP(F31,[1]对照表!$G$3:$G$24,[1]对照表!$H$3:$H$24),LOOKUP(F31,[1]对照表!$G$27:$G$48,[1]对照表!$H$27:$H$48)),IF(B31="高二",IF($E31="男",LOOKUP(F31,[1]对照表!$F$3:$F$24,[1]对照表!$H$3:$H$24),LOOKUP(F31,[1]对照表!$F$27:$F$48,[1]对照表!$H$27:$H$48)),IF(B31="高一",IF($E31="男",LOOKUP(F31,[1]对照表!$E$3:$E$24,[1]对照表!$H$3:$H$24),LOOKUP(F31,[1]对照表!$E$27:$E$48,[1]对照表!$H$27:$H$48))))) -> 74 | H31: 11.5 | I31: =IF(B31="高三",IF($E31="男",LOOKUP(H31,[1]对照表!$K$3:$K$24,[1]对照表!$L$3:$L$24),LOOKUP(H31,[1]对照表!$K$27:$K$48,[1]对照表!$L$27:$L$48)),IF(B31="高二",IF($E31="男",LOOKUP(H31,[1]对照表!$J$3:$J$24,[1]对照表!$L$3:$L$24),LOOKUP(H31,[1]对照表!$J$27:$J$48,[1]对照表!$L$27:$L$48)),IF(B31="高一",IF($E31="男",LOOKUP(H31,[1]对照表!$I$3:$I$24,[1]对照表!$L$3:$L$24),LOOKUP(H31,[1]对照表!$I$27:$I$48,[1]对照表!$L$27:$L$48))))) -> 74 | J31: 208 | K31: =IF(B31="高三",IF($E31="男",LOOKUP(J31,[1]对照表!$O$3:$O$24,[1]对照表!$P$3:$P$24),LOOKUP(J31,[1]对照表!$O$27:$O$48,[1]对照表!$P$27:$P$48)),IF(B31="高二",IF($E31="男",LOOKUP(J31,[1]对照表!$N$3:$N$24,[1]对照表!$P$3:$P$24),LOOKUP(J31,[1]对照表!$N$27:$N$48,[1]对照表!$P$27:$P$48)),IF(B31="高一",IF($E31="男",LOOKUP(J31,[1]对照表!$M$3:$M$24,[1]对照表!$P$3:$P$24),LOOKUP(J31,[1]对照表!$M$27:$M$48,[1]对照表!$P$27:$P$48))))) -> 66 | L31: 10 | M31: =IF(B31="高三",IF($E31="男",LOOKUP(L31,[1]对照表!$S$3:$S$24,[1]对照表!$T$3:$T$24),LOOKUP(L31,[1]对照表!$S$27:$S$48,[1]对照表!$T$27:$T$48)),IF(B31="高二",IF($E31="男",LOOKUP(L31,[1]对照表!$R$3:$R$24,[1]对照表!$T$3:$T$24),LOOKUP(L31,[1]对照表!$R$27:$R$48,[1]对照表!$T$27:$T$48)),IF(B31="高一",IF($E31="男",LOOKUP(L31,[1]对照表!$Q$3:$Q$24,[1]对照表!$T$3:$T$24),LOOKUP(L31,[1]对照表!$Q$27:$Q$48,[1]对照表!$T$27:$T$48))))) -> 72 | N31: =IF(B31="高三",MAX(IF(E31="男",L31-18,L31-55),0),IF(B31="高二",MAX(IF(E31="男",L31-17,L31-54),0),IF(B31="高一",MAX(IF(E31="男",L31-16,L31-53),0)))) -> 0 | O31: =IF(E31="男",LOOKUP($N31,[1]对照表!$Z$3:$Z$13,[1]对照表!$AA$3:$AA$13),LOOKUP($N31,[1]对照表!$Z$15:$Z$25,[1]对照表!$AA$15:$AA$25)) -> 0 | P31: =M31+O31 -> 72 | Q31: 4.08 | R31: =IF(B31="高三",IF($E31="男",LOOKUP(Q31,[1]对照表!$W$3:$W$24,[1]对照表!$X$3:$X$24),LOOKUP(Q31,[1]对照表!$W$27:$W$48,[1]对照表!$X$27:$X$48)),IF(B31="高二",IF($E31="男",LOOKUP(Q31,[1]对照表!$V$3:$V$24,[1]对照表!$X$3:$X$24),LOOKUP(Q31,[1]对照表!$V$27:$V$48,[1]对照表!$X$27:$X$48)),IF(B31="高一",IF($E31="男",LOOKUP(Q31,[1]对照表!$U$3:$U$24,[1]对照表!$X$3:$X$24),LOOKUP(Q31,[1]对照表!$U$27:$U$48,[1]对照表!$X$27:$X$48))))) -> 74 | S31: =ROUND(IF(IF($B31="高三",MIN(IF($E31="男",$Q31-3.2,$Q31-3.2),0),IF($B31="高二",MIN(IF($E31="男",$Q31-3.25,$Q31-3.22),0),IF($B31="高一",MIN(IF($E31="男",$Q31-3.3,$Q31-3.24),0))))<-0.6,IF($B31="高三",MIN(IF($E31="男",$Q31-3.2,$Q31-3.2),0),IF($B31="高二",MIN(IF($E31="男",$Q31-3.25,$Q31-3.22),0),IF($B31="高一",MIN(IF($E31="男",$Q31-3.3,$Q31-3.24),0))))+0.4,IF($B31="高三",MIN(IF($E31="男",$Q31-3.2,$Q31-3.2),0),IF($B31="高二",MIN(IF($E31="男",$Q31-3.25,$Q31-3.22),0),IF($B31="高一",MIN(IF($E31="男",$Q31-3.3,$Q31-3.24),0))))),2) -> 0 | T31: =IF(E31="男",LOOKUP($S31,[1]对照表!$AB$3:$AB$13,[1]对照表!$AC$3:$AC$13),LOOKUP($S31,[1]对照表!$AB$15:$AB$25,[1]对照表!$AC$15:$AC$25)) -> 0 | U31: =R31+T31 -> 74 | V31: =SUM(I31,K31,M31)/3*0.3+SUM(G31,R31)/2*0.4 -> 50.8 | W31: =O31+T31 -> 0 | X31: =V31/0.7+W31 -> 72.571429 | Y31: 72.571429
